Workbook

Sheet 车辆工程
A1: 序号 | B1: 学号 | C1: 姓名 | D1: 班级 | E1: 课程成绩 本专业名 次 | F1: 课程成绩本 专业排名百 分比 | G1: 课程成绩计算结果 | H1: 纳入计算 的课程数 | I1: 纳入计算课程 获得总学分 | J1: 不及格课 程门数 | K1: 不及格课 程已通过 门数 | L1: 是否通过全 国大学英语 四级 | M1: 第1学期其他表现 | N1: 第2学期其他表现 | O1: 第3学期其他表现 | P1: 第4学期其他表现 | Q1: 第5学期其他表现 | R1: 第6学期其他表现 | S1: 其他表现成绩 | T1: 其他表现 排名名次 | U1: 综合成绩 | V1: 综合 成绩 | W1: 综合排名 名次 | X1: 排名 人数 | Y1: 专业 | Z1: 备注
A2: 1 | B2: 1120233372 | C2: 张倬熙 | D2: =VLOOKUP([1]成绩单!B2,[1]Sheet1!$A:$K,4,0) -> 精工2310 | E2: 1 | F2: 0.010526 | G2: 94.46 | H2: 65 | I2: 137.5 | J2: 0 | K2: 0 | L2: 是 | M2: 5.6 | N2: 9.8 | O2: 22.6 | P2: 15.4 | Q2: 30.2 | S2: =SUM(M2:Q2) -> 83.6 | T2: =COUNTIFS($Y:$Y, Y2, $S:$S, ">"&S2) + 1 -> 1 | U2: =0.85*E2+T2*0.15 -> 1 | V2: =100.4-0.4*W2 -> 100 | W2: =COUNTIFS($Y:$Y, Y2, $U:$U, "<"&U2) + 1 -> 1 | X2: 95 | Y2: 车辆工程
A3: 2 | B3: 1120230331 | C3: 张子凯 | D3: =VLOOKUP([1]成绩单!B3,[1]Sheet1!$A:$K,4,0) -> 精工2311 | E3: 2 | F3: 0.021053 | G3: 93.3579 | H3: 64 | I3: 135.5 | J3: 0 | K3: 0 | L3: 是 | M3: 3.8 | N3: 6.3 | O3: 14.3 | P3: 22.2 | Q3: 18.8 | S3: =SUM(M3:Q3) -> 65.4 | T3: =COUNTIFS($Y:$Y, Y3, $S:$S, ">"&S3) + 1 -> 2 | U3: =0.85*E3+T3*0.15 -> 2 | V3: =100.4-0.4*W3 -> 99.6 | W3: =COUNTIFS($Y:$Y, Y3, $U:$U, "<"&U3) + 1 -> 2 | X3: 95 | Y3: 车辆工程
A4: 3 | B4: 1120232880 | C4: 张焱鑫 | D4: =VLOOKUP([1]成绩单!B5,[1]Sheet1!$A:$K,4,0) -> 精工2311 | E4: 4 | F4: 0.042105 | G4: 92.7918 | H4: 62 | I4: 134.5 | J4: 0 | K4: 0 | L4: 是 | M4: 7.8 | N4: 2.8 | O4: 12.68 | P4: 5.9 | Q4: 11.8 | S4: =SUM(M4:Q4) -> 40.98 | T4: =COUNTIFS($Y:$Y, Y4, $S:$S, ">"&S4) + 1 -> 11 | U4: =0.85*E4+T4*0.15 -> 5.05 | V4: =100.4-0.4*W4 -> 99.2 | W4: =COUNTIFS($Y:$Y, Y4, $U:$U, "<"&U4) + 1 -> 3 | X4: 95 | Y4: 车辆工程
A5: 4 | B5: 1120231019 | C5: 杨轶铭 | D5: =VLOOKUP([1]成绩单!B6,[1]Sheet1!$A:$K,4,0) -> 精工2310 | E5: 5 | F5: 0.052632 | G5: 92.435 | H5: 64 | I5: 138.5 | J5: 0 | K5: 0 | L5: 是 | M5: 1.3 | N5: 1.5 | O5: 4.6 | P5: 17 | Q5: 18.7 | S5: =SUM(M5:Q5) -> 43.1 | T5: =COUNTIFS($Y:$Y, Y5, $S:$S, ">"&S5) + 1 -> 10 | U5: =0.85*E5+T5*0.15 -> 5.75 | V5: =100.4-0.4*W5 -> 98.8 | W5: =COUNTIFS($Y:$Y, Y5, $U:$U, "<"&U5) + 1 -> 4 | X5: 95 | Y5: 车辆工程
A6: 5 | B6: 1120231642 | C6: 李鑫 | D6: =VLOOKUP([1]成绩单!B7,[1]Sheet1!$A:$K,4,0) -> 精工2312 | E6: 6 | F6: 0.063158 | G6: 91.2744 | H6: 66 | I6: 138.5 | J6: 0 | K6: 0 | L6: 是 | M6: 3.5 | N6: 7.8 | O6: 8.5 | P6: 7.7 | Q6: 4.6 | S6: =SUM(M6:Q6) -> 32.1 | T6: =COUNTIFS($Y:$Y, Y6, $S:$S, ">"&S6) + 1 -> 21 | U6: =0.85*E6+T6*0.15 -> 8.25 | V6: =100.4-0.4*W6 -> 98.4 | W6: =COUNTIFS($Y:$Y, Y6, $U:$U, "<"&U6) + 1 -> 5 | X6: 95 | Y6: 车辆工程
A7: 6 | B7: 1120233376 | C7: 王乐桐 | D7: =VLOOKUP([1]成绩单!B4,[1]Sheet1!$A:$K,4,0) -> 精工2310 | E7: 3 | F7: 0.031579 | G7: 93.1696 | H7: 65 | I7: 141.5 | J7: 0 | K7: 0 | L7: 是 | M7: 2.7 | N7: 5.7 | O7: 6.9 | P7: 0.6 | Q7: 0.7 | S7: =SUM(M7:Q7) -> 16.6 | T7: =COUNTIFS($Y:$Y, Y7, $S:$S, ">"&S7) + 1 -> 44 | U7: =0.85*E7+T7*0.15 -> 9.15 | V7: =100.4-0.4*W7 -> 98 | W7: =COUNTIFS($Y:$Y, Y7, $U:$U, "<"&U7) + 1 -> 6 | X7: 95 | Y7: 车辆工程
A8: 7 | B8: 1120230370 | C8: 蒋濮羽 | D8: =VLOOKUP([1]成绩单!B8,[1]Sheet1!$A:$K,4,0) -> 精工2313 | E8: 7 | F8: 0.073684 | G8: 91.1891 | H8: 62 | I8: 133.5 | J8: 0 | K8: 0 | L8: 是 | M8: 2.3 | N8: 6.5 | O8: 12 | P8: 7.5 | Q8: 2.5 | S8: =SUM(M8:Q8) -> 30.8 | T8: =COUNTIFS($Y:$Y, Y8, $S:$S, ">"&S8) + 1 -> 23 | U8: =0.85*E8+T8*0.15 -> 9.4 | V8: =100.4-0.4*W8 -> 97.6 | W8: =COUNTIFS($Y:$Y, Y8, $U:$U, "<"&U8) + 1 -> 7 | X8: 95 | Y8: 车辆工程
A9: 8 | B9: 1120230216 | C9: 徐雷 | D9: =VLOOKUP([1]成绩单!B11,[1]Sheet1!$A:$K,4,0) -> 精工2311 | E9: 10 | F9: 0.105263 | G9: 90.6355 | H9: 63 | I9: 136.5 | J9: 0 | K9: 0 | L9: 是 | M9: 5.7 | N9: 7.7 | O9: 5.9 | P9: 5.8 | Q9: 6.5 | S9: =SUM(M9:Q9) -> 31.6 | T9: =COUNTIFS($Y:$Y, Y9, $S:$S, ">"&S9) + 1 -> 22 | U9: =0.85*E9+T9*0.15 -> 11.8 | V9: =100.4-0.4*W9 -> 97.2 | W9: =COUNTIFS($Y:$Y, Y9, $U:$U, "<"&U9) + 1 -> 8 | X9: 95 | Y9: 车辆工程
A10: 9 | B10: 1120232505 | C10: 王星媛 | D10: =VLOOKUP([1]成绩单!B9,[1]Sheet1!$A:$K,4,0) -> 精工2311 | E10: 8 | F10: 0.084211 | G10: 90.87 | H10: 64 | I10: 138.5 | J10: 0 | K10: 0 | L10: 是 | M10: 1 | N10: 3.5 | O10: 7.3 | P10: 5.6 | Q10: 3.9 | S10: =SUM(M10:Q10) -> 21.3 | T10: =COUNTIFS($Y:$Y, Y10, $S:$S, ">"&S10) + 1 -> 39 | U10: =0.85*E10+T10*0.15 -> 12.65 | V10: =100.4-0.4*W10 -> 96.8 | W10: =COUNTIFS($Y:$Y, Y10, $U:$U, "<"&U10) + 1 -> 9 | X10: 95 | Y10: 车辆工程
A11: 10 | B11: 1120231525 | C11: 尹梦萍 | D11: =VLOOKUP([1]成绩单!B15,[1]Sheet1!$A:$K,4,0) -> 精工2311 | E11: 14 | F11: 0.147368 | G11: 90.0448 | H11: 65 | I11: 139.5 | J11: 0 | K11: 0 | L11: 是 | M11: 4.1 | N11: 10.3 | O11: 8.8 | P11: 7 | Q11: 22.8 | S11: =SUM(M11:Q11) -> 53 | T11: =COUNTIFS($Y:$Y, Y11, $S:$S, ">"&S11) + 1 -> 5 | U11: =0.85*E11+T11*0.15 -> 12.65 | V11: =100.4-0.4*W11 -> 96.8 | W11: =COUNTIFS($Y:$Y, Y11, $U:$U, "<"&U11) + 1 -> 9 | X11: 95 | Y11: 车辆工程
A12: 11 | B12: 1120231293 | C12: 谭星宇 | D12: =VLOOKUP([1]成绩单!B10,[1]Sheet1!$A:$K,4,0) -> 精工2312 | E12: 9 | F12: 0.094737 | G12: 90.6989 | H12: 62 | I12: 134.5 | J12: 0 | K12: 0 | L12: 是 | M12: 2 | N12: 2.85 | O12: 4.3 | P12: 6.6 | Q12: 7.5 | S12: =SUM(M12:Q12) -> 23.25 | T12: =COUNTIFS($Y:$Y, Y12, $S:$S, ">"&S12) + 1 -> 36 | U12: =0.85*E12+T12*0.15 -> 13.05 | V12: =100.4-0.4*W12 -> 96 | W12: =COUNTIFS($Y:$Y, Y12, $U:$U, "<"&U12) + 1 -> 11 | X12: 95 | Y12: 车辆工程
A13: 12 | B13: 1120231622 | C13: 张建鹏 | D13: =VLOOKUP([1]成绩单!B16,[1]Sheet1!$A:$K,4,0) -> 精工2310 | E13: 15 | F13: 0.157895 | G13: 90.0413 | H13: 71 | I13: 151.5 | J13: 0 | K13: 0 | L13: 是 | M13: 1 | N13: 8.9 | O13: 12 | P13: 12.8 | Q13: 13.8 | S13: =SUM(M13:Q13) -> 48.5 | T13: =COUNTIFS($Y:$Y, Y13, $S:$S, ">"&S13) + 1 -> 7 | U13: =0.85*E13+T13*0.15 -> 13.8 | V13: =100.4-0.4*W13 -> 95.6 | W13: =COUNTIFS($Y:$Y, Y13, $U:$U, "<"&U13) + 1 -> 12 | X13: 95 | Y13: 车辆工程
A14: 13 | B14: 1120233389 | C14: 韩金言 | D14: =VLOOKUP([1]成绩单!B17,[1]Sheet1!$A:$K,4,0) -> 精工2313 | E14: 16 | F14: 0.168421 | G14: 89.7641 | H14: 72 | I14: 150.5 | J14: 0 | K14: 0 | L14: 是 | M14: 7 | N14: 10.5 | O14: 10.3 | P14: 15.7 | Q14: 10.5 | S14: =SUM(M14:Q14) -> 54 | T14: =COUNTIFS($Y:$Y, Y14, $S:$S, ">"&S14) + 1 -> 3 | U14: =0.85*E14+T14*0.15 -> 14.05 | V14: =100.4-0.4*W14 -> 95.2 | W14: =COUNTIFS($Y:$Y, Y14, $U:$U, "<"&U14) + 1 -> 13 | X14: 95 | Y14: 车辆工程
A15: 14 | B15: 1120233251 | C15: 寸涛鸣 | D15: =VLOOKUP([1]成绩单!B14,[1]Sheet1!$A:$K,4,0) -> 精工2313 | E15: 13 | F15: 0.136842 | G15: 90.0641 | H15: 65 | I15: 140.5 | J15: 0 | K15: 0 | L15: 是 | M15: 0.8 | N15: 2 | O15: 1.6 | P15: 3.6 | Q15: 18.05 | S15: =SUM(M15:Q15) -> 26.05 | T15: =COUNTIFS($Y:$Y, Y15, $S:$S, ">"&S15) + 1 -> 29 | U15: =0.85*E15+T15*0.15 -> 15.4 | V15: =100.4-0.4*W15 -> 94.8 | W15: =COUNTIFS($Y:$Y, Y15, $U:$U, "<"&U15) + 1 -> 14 | X15: 95 | Y15: 车辆工程
A16: 15 | B16: 1120230994 | C16: 钟宇宸 | D16: =VLOOKUP([1]成绩单!B13,[1]Sheet1!$A:$K,4,0) -> 精工2313 | E16: 12 | F16: 0.126316 | G16: 90.2015 | H16: 63 | I16: 136.5 | J16: 0 | K16: 0 | L16: 是 | M16: 1.9 | N16: 3.75 | O16: 5.5 | P16: 4.1 | Q16: 2.2 | S16: =SUM(M16:Q16) -> 17.45 | T16: =COUNTIFS($Y:$Y, Y16, $S:$S, ">"&S16) + 1 -> 42 | U16: =0.85*E16+T16*0.15 -> 16.5 | V16: =100.4-0.4*W16 -> 94.4 | W16: =COUNTIFS($Y:$Y, Y16, $U:$U, "<"&U16) + 1 -> 15 | X16: 95 | Y16: 车辆工程
A17: 16 | B17: 1120231016 | C17: 王为鸣 | D17: =VLOOKUP([1]成绩单!B20,[1]Sheet1!$A:$K,4,0) -> 精工2312 | E17: 19 | F17: 0.2 | G17: 89.5392 | H17: 68 | I17: 146.5 | J17: 0 | K17: 0 | L17: 是 | M17: 3.85 | N17: 7.3 | O17: 7.3 | P17: 10.9 | Q17: 5.8 | S17: =SUM(M17:Q17) -> 35.15 | T17: =COUNTIFS($Y:$Y, Y17, $S:$S, ">"&S17) + 1 -> 18 | U17: =0.85*E17+T17*0.15 -> 18.85 | V17: =100.4-0.4*W17 -> 94 | W17: =COUNTIFS($Y:$Y, Y17, $U:$U, "<"&U17) + 1 -> 16 | X17: 95 | Y17: 车辆工程
A18: 17 | B18: 1120232293 | C18: 姜政宇 | D18: =VLOOKUP([1]成绩单!B12,[1]Sheet1!$A:$K,4,0) -> 精工2312 | E18: 11 | F18: 0.115789 | G18: 90.2943 | H18: 61 | I18: 132.5 | J18: 0 | K18: 0 | L18: 是 | M18: 1.5 | N18: 2 | O18: 2 | P18: 2 | Q18: 1.5 | S18: =SUM(M18:Q18) -> 9 | T18: =COUNTIFS($Y:$Y, Y18, $S:$S, ">"&S18) + 1 -> 69 | U18: =0.85*E18+T18*0.15 -> 19.7 | V18: =100.4-0.4*W18 -> 93.6 | W18: =COUNTIFS($Y:$Y, Y18, $U:$U, "<"&U18) + 1 -> 17 | X18: 95 | Y18: 车辆工程
A19: 18 | B19: 1120230828 | C19: 杨昇 | D19: =VLOOKUP([1]成绩单!B18,[1]Sheet1!$A:$K,4,0) -> 精工2311 | E19: 17 | F19: 0.178947 | G19: 89.7637 | H19: 63 | I19: 136.5 | J19: 0 | K19: 0 | L19: 是 | M19: 2.65 | N19: 3 | O19: 2.3 | P19: 3.8 | Q19: 6.3 | S19: =SUM(M19:Q19) -> 18.05 | T19: =COUNTIFS($Y:$Y, Y19, $S:$S, ">"&S19) + 1 -> 41 | U19: =0.85*E19+T19*0.15 -> 20.6 | V19: =100.4-0.4*W19 -> 93.2 | W19: =COUNTIFS($Y:$Y, Y19, $U:$U, "<"&U19) + 1 -> 18 | X19: 95 | Y19: 车辆工程
A20: 19 | B20: 1120230268 | C20: 彭琛朗 | D20: =VLOOKUP([1]成绩单!B19,[1]Sheet1!$A:$K,4,0) -> 精工2311 | E20: 18 | F20: 0.189474 | G20: 89.5549 | H20: 63 | I20: 136.5 | J20: 0 | K20: 0 | L20: 是 | M20: 0.8 | N20: 2.2 | O20: 6.35 | P20: 4.2 | Q20: 6.7 | S20: =SUM(M20:Q20) -> 20.25 | T20: =COUNTIFS($Y:$Y, Y20, $S:$S, ">"&S20) + 1 -> 40 | U20: =0.85*E20+T20*0.15 -> 21.3 | V20: =100.4-0.4*W20 -> 92.8 | W20: =COUNTIFS($Y:$Y, Y20, $U:$U, "<"&U20) + 1 -> 19 | X20: 95 | Y20: 车辆工程
A21: 20 | B21: 1120233387 | C21: 罗浩然 | D21: =VLOOKUP([1]成绩单!B23,[1]Sheet1!$A:$K,4,0) -> 精工2312 | E21: 22 | F21: 0.231579 | G21: 89.0341 | H21: 65 | I21: 139.5 | J21: 0 | K21: 0 | L21: 是 | M21: 5.4 | N21: 1.5 | O21: 7.1 | P21: 5.9 | Q21: 12.6 | S21: =SUM(M21:Q21) -> 32.5 | T21: =COUNTIFS($Y:$Y, Y21, $S:$S, ">"&S21) + 1 -> 20 | U21: =0.85*E21+T21*0.15 -> 21.7 | V21: =100.4-0.4*W21 -> 92.4 | W21: =COUNTIFS($Y:$Y, Y21, $U:$U, "<"&U21) + 1 -> 20 | X21: 95 | Y21: 车辆工程
A22: 21 | B22: 1120233006 | C22: 张焕纯 | D22: =VLOOKUP([1]成绩单!B24,[1]Sheet1!$A:$K,4,0) -> 精工2312 | E22: 23 | F22: 0.242105 | G22: 89.0167 | H22: 63 | I22: 134.5 | J22: 0 | K22: 0 | L22: 是 | M22: 0 | N22: 1 | O22: 9 | P22: 10 | Q22: 10 | S22: =SUM(M22:Q22) -> 30 | T22: =COUNTIFS($Y:$Y, Y22, $S:$S, ">"&S22) + 1 -> 24 | U22: =0.85*E22+T22*0.15 -> 23.15 | V22: =100.4-0.4*W22 -> 92 | W22: =COUNTIFS($Y:$Y, Y22, $U:$U, "<"&U22) + 1 -> 21 | X22: 95 | Y22: 车辆工程
A23: 22 | B23: 1120232489 | C23: 仇自羽 | D23: =VLOOKUP([1]成绩单!B27,[1]Sheet1!$A:$K,4,0) -> 精工2312 | E23: 26 | F23: 0.273684 | G23: 88.8 | H23: 64 | I23: 137.5 | J23: 0 | K23: 0 | L23: 是 | M23: 3.2 | N23: 4.3 | O23: 16.4 | P23: 9.2 | Q23: 7 | S23: =SUM(M23:Q23) -> 40.1 | T23: =COUNTIFS($Y:$Y, Y23, $S:$S, ">"&S23) + 1 -> 12 | U23: =0.85*E23+T23*0.15 -> 23.9 | V23: =100.4-0.4*W23 -> 91.6 | W23: =COUNTIFS($Y:$Y, Y23, $U:$U, "<"&U23) + 1 -> 22 | X23: 95 | Y23: 车辆工程
A24: 23 | B24: 1120231656 | C24: 王敬源 | D24: =VLOOKUP([1]成绩单!B21,[1]Sheet1!$A:$K,4,0) -> 精工2313 | E24: 20 | F24: 0.210526 | G24: 89.0989 | H24: 66 | I24: 141.5 | J24: 0 | K24: 0 | L24: 是 | M24: 2.6 | N24: 1.7 | O24: 5.5 | P24: 2 | Q24: 3.7 | S24: =SUM(M24:Q24) -> 15.5 | T24: =COUNTIFS($Y:$Y, Y24, $S:$S, ">"&S24) + 1 -> 47 | U24: =0.85*E24+T24*0.15 -> 24.05 | V24: =100.4-0.4*W24 -> 91.2 | W24: =COUNTIFS($Y:$Y, Y24, $U:$U, "<"&U24) + 1 -> 23 | X24: 95 | Y24: 车辆工程
A25: 24 | B25: 1120232875 | C25: 何宣佐 | D25: =VLOOKUP([1]成绩单!B26,[1]Sheet1!$A:$K,4,0) -> 精工2311 | E25: 25 | F25: 0.263158 | G25: 88.853 | H25: 65 | I25: 139.5 | J25: 0 | K25: 0 | L25: 是 | M25: 2.4 | N25: 0.8 | O25: 12.2 | P25: 5 | Q25: 8.5 | S25: =SUM(M25:Q25) -> 28.9 | T25: =COUNTIFS($Y:$Y, Y25, $S:$S, ">"&S25) + 1 -> 25 | U25: =0.85*E25+T25*0.15 -> 25 | V25: =100.4-0.4*W25 -> 90.8 | W25: =COUNTIFS($Y:$Y, Y25, $U:$U, "<"&U25) + 1 -> 24 | X25: 95 | Y25: 车辆工程
A26: 25 | B26: 1120231612 | C26: 尹毅 | D26: =VLOOKUP([1]成绩单!B25,[1]Sheet1!$A:$K,4,0) -> 精工2312 | E26: 24 | F26: 0.252632 | G26: 88.9682 | H26: 66 | I26: 141.5 | J26: 0 | K26: 0 | L26: 是 | M26: 0.2 | N26: 1.2 | O26: 5 | P26: 4.65 | Q26: 14.14 | S26: =SUM(M26:Q26) -> 25.19 | T26: =COUNTIFS($Y:$Y, Y26, $S:$S, ">"&S26) + 1 -> 34 | U26: =0.85*E26+T26*0.15 -> 25.5 | V26: =100.4-0.4*W26 -> 90.4 | W26: =COUNTIFS($Y:$Y, Y26, $U:$U, "<"&U26) + 1 -> 25 | X26: 95 | Y26: 车辆工程
A27: 26 | B27: 1120231778 | C27: 杨光 | D27: =VLOOKUP([1]成绩单!B22,[1]Sheet1!$A:$K,4,0) -> 精工2310 | E27: 21 | F27: 0.221053 | G27: 89.0657 | H27: 66 | I27: 140.75 | J27: 0 | K27: 0 | L27: 是 | M27: 0.5 | N27: 5 | O27: 4.3 | P27: 2 | Q27: 0.75 | S27: =SUM(M27:Q27) -> 12.55 | T27: =COUNTIFS($Y:$Y, Y27, $S:$S, ">"&S27) + 1 -> 55 | U27: =0.85*E27+T27*0.15 -> 26.1 | V27: =100.4-0.4*W27 -> 90 | W27: =COUNTIFS($Y:$Y, Y27, $U:$U, "<"&U27) + 1 -> 26 | X27: 95 | Y27: 车辆工程
A28: 27 | B28: 1120232495 | C28: 邹子航 | D28: =VLOOKUP([1]成绩单!B31,[1]Sheet1!$A:$K,4,0) -> 精工2313 | E28: 30 | F28: 0.315789 | G28: 87.7685 | H28: 63 | I28: 135 | J28: 0 | K28: 0 | L28: 是 | M28: 0.3 | N28: 5.84 | O28: 17.4 | P28: 5.15 | Q28: 8.7 | S28: =SUM(M28:Q28) -> 37.39 | T28: =COUNTIFS($Y:$Y, Y28, $S:$S, ">"&S28) + 1 -> 16 | U28: =0.85*E28+T28*0.15 -> 27.9 | V28: =100.4-0.4*W28 -> 89.6 | W28: =COUNTIFS($Y:$Y, Y28, $U:$U, "<"&U28) + 1 -> 27 | X28: 95 | Y28: 车辆工程
A29: 28 | B29: 1120231433 | C29: 陈天润 | D29: =VLOOKUP([1]成绩单!B32,[1]Sheet1!$A:$K,4,0) -> 精工2310 | E29: 31 | F29: 0.326316 | G29: 87.3817 | H29: 74 | I29: 158.5 | J29: 0 | K29: 0 | L29: 是 | M29: 1.8 | N29: 4.48 | O29: 7.5 | P29: 10.8 | Q29: 9.7 | S29: =SUM(M29:Q29) -> 34.28 | T29: =COUNTIFS($Y:$Y, Y29, $S:$S, ">"&S29) + 1 -> 19 | U29: =0.85*E29+T29*0.15 -> 29.2 | V29: =100.4-0.4*W29 -> 89.2 | W29: =COUNTIFS($Y:$Y, Y29, $U:$U, "<"&U29) + 1 -> 28 | X29: 95 | Y29: 车辆工程
A30: 29 | B30: 1120231631 | C30: 陈佳楠 | D30: =VLOOKUP([1]成绩单!B28,[1]Sheet1!$A:$K,4,0) -> 精工2313 | E30: 27 | F30: 0.284211 | G30: 88.5948 | H30: 63 | I30: 134.5 | J30: 0 | K30: 0 | L30: 是 | M30: 0.5 | N30: 1.2 | O30: 5.3 | P30: 1.5 | Q30: 7.6 | S30: =SUM(M30:Q30) -> 16.1 | T30: =COUNTIFS($Y:$Y, Y30, $S:$S, ">"&S30) + 1 -> 45 | U30: =0.85*E30+T30*0.15 -> 29.7 | V30: =100.4-0.4*W30 -> 88.8 | W30: =COUNTIFS($Y:$Y, Y30, $U:$U, "<"&U30) + 1 -> 29 | X30: 95 | Y30: 车辆工程
A31: 30 | B31: 1120231762 | C31: 曹清淞 | D31: =VLOOKUP([1]成绩单!B35,[1]Sheet1!$A:$K,4,0) -> 精工2310 | E31: 34 | F31: 0.357895 | G31: 87.0636 | H31: 67 | I31: 141.5 | J31: 0 | K31: 0 | L31: 是 | M31: 1.7 | N31: 6.2 | O31: 9.4 | P31: 10.6 | Q31: 10.2 | S31: =SUM(M31:Q31) -> 38.1 | T31: =COUNTIFS($Y:$Y, Y31, $S:$S, ">"&S31) + 1 -> 15 | U31: =0.85*E31+T31*0.15 -> 31.15 | V31: =100.4-0.4*W31 -> 88.4 | W31: =COUNTIFS($Y:$Y, Y31, $U:$U, "<"&U31) + 1 -> 30 | X31: 95 | Y31: 车辆工程
A32: 31 | B32: 1120232294 | C32: 王子卿 | D32: =VLOOKUP([1]成绩单!B29,[1]Sheet1!$A:$K,4,0) -> 精工2312 | E32: 28 | F32: 0.294737 | G32: 88.3045 | H32: 64 | I32: 138.75 | J32: 0 | K32: 0 | L32: 是 | M32: 2.15 | N32: 1.7 | O32: 3.2 | P32: 5.7 | Q32: 1.2 | S32: =SUM(M32:Q32) -> 13.95 | T32: =COUNTIFS($Y:$Y, Y32, $S:$S, ">"&S32) + 1 -> 50 | U32: =0.85*E32+T32*0.15 -> 31.3 | V32: =100.4-0.4*W32 -> 88 | W32: =COUNTIFS($Y:$Y, Y32, $U:$U, "<"&U32) + 1 -> 31 | X32: 95 | Y32: 车辆工程
A33: 32 | B33: 1120232903 | C33: 陈俊利 | D33: =VLOOKUP([1]成绩单!B33,[1]Sheet1!$A:$K,4,0) -> 精工2312 | E33: 32 | F33: 0.336842 | G33: 87.2921 | H33: 64 | I33: 139.5 | J33: 0 | K33: 0 | L33: 是 | M33: 1.3 | N33: 3.2 | O33: 8.35 | P33: 6.15 | Q33: 7 | S33: =SUM(M33:Q33) -> 26 | T33: =COUNTIFS($Y:$Y, Y33, $S:$S, ">"&S33) + 1 -> 30 | U33: =0.85*E33+T33*0.15 -> 31.7 | V33: =100.4-0.4*W33 -> 87.6 | W33: =COUNTIFS($Y:$Y, Y33, $U:$U, "<"&U33) + 1 -> 32 | X33: 95 | Y33: 车辆工程
A34: 33 | B34: 1120231358 | C34: 沈哲彦 | D34: =VLOOKUP([1]成绩单!B37,[1]Sheet1!$A:$K,4,0) -> 精工2313 | E34: 36 | F34: 0.378947 | G34: 86.953 | H34: 67 | I34: 143.5 | J34: 0 | K34: 0 | L34: 是 | M34: 2.7 | N34: 6.7 | O34: 11.6 | P34: 10.6 | Q34: 14.8 | S34: =SUM(M34:Q34) -> 46.4 | T34: =COUNTIFS($Y:$Y, Y34, $S:$S, ">"&S34) + 1 -> 9 | U34: =0.85*E34+T34*0.15 -> 31.95 | V34: =100.4-0.4*W34 -> 87.2 | W34: =COUNTIFS($Y:$Y, Y34, $U:$U, "<"&U34) + 1 -> 33 | X34: 95 | Y34: 车辆工程
A35: 34 | B35: 1120232519 | C35: 徐潇怡 | D35: =VLOOKUP([1]成绩单!B34,[1]Sheet1!$A:$K,4,0) -> 精工2310 | E35: 33 | F35: 0.347368 | G35: 87.1572 | H35: 66 | I35: 141.5 | J35: 0 | K35: 0 | L35: 是 | M35: 2.8 | N35: 0.4 | O35: 3.7 | P35: 6 | Q35: 13.3 | S35: =SUM(M35:Q35) -> 26.2 | T35: =COUNTIFS($Y:$Y, Y35, $S:$S, ">"&S35) + 1 -> 28 | U35: =0.85*E35+T35*0.15 -> 32.25 | V35: =100.4-0.4*W35 -> 86.8 | W35: =COUNTIFS($Y:$Y, Y35, $U:$U, "<"&U35) + 1 -> 34 | X35: 95 | Y35: 车辆工程
A36: 35 | B36: 1120232761 | C36: 谌力 | D36: =VLOOKUP([1]成绩单!B30,[1]Sheet1!$A:$K,4,0) -> 精工2310 | E36: 29 | F36: 0.305263 | G36: 87.9636 | H36: 64 | I36: 137.5 | J36: 0 | K36: 0 | L36: 是 | M36: 1.2 | N36: 2.2 | O36: 2.3 | P36: 2.5 | Q36: 4.5 | S36: =SUM(M36:Q36) -> 12.7 | T36: =COUNTIFS($Y:$Y, Y36, $S:$S, ">"&S36) + 1 -> 54 | U36: =0.85*E36+T36*0.15 -> 32.75 | V36: =100.4-0.4*W36 -> 86.4 | W36: =COUNTIFS($Y:$Y, Y36, $U:$U, "<"&U36) + 1 -> 35 | X36: 95 | Y36: 车辆工程
A37: 36 | B37: 1120231024 | C37: 罗薇 | D37: =VLOOKUP([1]成绩单!B43,[1]Sheet1!$A:$K,4,0) -> 精工2311 | E37: 42 | F37: 0.442105 | G37: 85.6575 | H37: 64 | I37: 136.5 | J37: 0 | K37: 0 | L37: 是 | M37: 5.7 | N37: 8.1 | O37: 8.5 | P37: 8.7 | Q37: 9 | S37: =SUM(M37:Q37) -> 40 | T37: =COUNTIFS($Y:$Y, Y37, $S:$S, ">"&S37) + 1 -> 13 | U37: =0.85*E37+T37*0.15 -> 37.65 | V37: =100.4-0.4*W37 -> 86 | W37: =COUNTIFS($Y:$Y, Y37, $U:$U, "<"&U37) + 1 -> 36 | X37: 95 | Y37: 车辆工程
A38: 37 | B38: 1120233391 | C38: 暴雨泽 | D38: =VLOOKUP([1]成绩单!B36,[1]Sheet1!$A:$K,4,0) -> 精工2311 | E38: 35 | F38: 0.368421 | G38: 86.9908 | H38: 63 | I38: 136.5 | J38: 0 | K38: 0 | L38: 是 | M38: 0.95 | N38: 1.8 | O38: 1.3 | P38: 1 | Q38: 7.7 | S38: =SUM(M38:Q38) -> 12.75 | T38: =COUNTIFS($Y:$Y, Y38, $S:$S, ">"&S38) + 1 -> 53 | U38: =0.85*E38+T38*0.15 -> 37.7 | V38: =100.4-0.4*W38 -> 85.6 | W38: =COUNTIFS($Y:$Y, Y38, $U:$U, "<"&U38) + 1 -> 37 | X38: 95 | Y38: 车辆工程
A39: 38 | B39: 1120232222 | C39: 陈禹男 | D39: =VLOOKUP([1]成绩单!B41,[1]Sheet1!$A:$K,4,0) -> 精工2313 | E39: 40 | F39: 0.421053 | G39: 86.0849 | H39: 63 | I39: 135.5 | J39: 0 | K39: 0 | L39: 是 | M39: 1.8 | N39: 2 | O39: 2.6 | P39: 8.5 | Q39: 13.4 | S39: =SUM(M39:Q39) -> 28.3 | T39: =COUNTIFS($Y:$Y, Y39, $S:$S, ">"&S39) + 1 -> 26 | U39: =0.85*E39+T39*0.15 -> 37.9 | V39: =100.4-0.4*W39 -> 85.2 | W39: =COUNTIFS($Y:$Y, Y39, $U:$U, "<"&U39) + 1 -> 38 | X39: 95 | Y39: 车辆工程
A40: 39 | B40: 1120231429 | C40: 蒋淞羽 | D40: =VLOOKUP([1]成绩单!B39,[1]Sheet1!$A:$K,4,0) -> 精工2310 | E40: 38 | F40: 0.4 | G40: 86.1245 | H40: 64 | I40: 136.5 | J40: 0 | K40: 0 | L40: 是 | M40: 4.8 | N40: 5.8 | O40: 4.7 | P40: 3.5 | Q40: 3.6 | S40: =SUM(M40:Q40) -> 22.4 | T40: =COUNTIFS($Y:$Y, Y40, $S:$S, ">"&S40) + 1 -> 38 | U40: =0.85*E40+T40*0.15 -> 38 | V40: =100.4-0.4*W40 -> 84.8 | W40: =COUNTIFS($Y:$Y, Y40, $U:$U, "<"&U40) + 1 -> 39 | X40: 95 | Y40: 车辆工程
...

Sheet 工业工程
A1: 序号 | B1: 学号 | C1: 姓名 | D1: 班级 | E1: 课程成绩 本专业名 次 | F1: 课程成绩本 专业排名百 分比 | G1: 课程成绩计算结果 | H1: 纳入计算 的课程数 | I1: 纳入计算课程 获得总学分 | J1: 不及格课 程门数 | K1: 不及格课 程已通过 门数 | L1: 是否通过全 国大学英语 四级 | M1: 第1学期其他表现 | N1: 第2学期其他表现 | O1: 第3学期其他表现 | P1: 第4学期其他表现 | Q1: 第5学期其他表现 | R1: 第6学期其他表现 | S1: 其他表现成绩 | T1: 其他表现 排名名次 | U1: 综合成绩 | V1: 综合 成绩 | W1: 综合排名 名次 | X1: 排名 人数 | Y1: 专业 | Z1: 备注
A2: 96 | B2: 1120230267 | C2: 王国伟 | D2: =VLOOKUP([1]成绩单!B2,[1]Sheet1!$A:$K,4,0) -> 精工2310 | E2: 1 | F2: 0.034483 | G2: 89.8996 | H2: 65 | I2: 142 | J2: 0 | K2: 0 | L2: 是 | M2: 2.2 | N2: 9.2 | O2: 12.4 | P2: 15.5 | Q2: 13.5 | S2: =SUM(M2:Q2) -> 52.8 | T2: =COUNTIFS($Y:$Y, Y2, $S:$S, ">"&S2) + 1 -> 2 | U2: =0.85*E2+T2*0.15 -> 1.15 | V2: =100.4-0.4*W2 -> 100 | W2: =COUNTIFS($Y:$Y, Y2, $U:$U, "<"&U2) + 1 -> 1 | X2: 29 | Y2: 工业工程
A3: 97 | B3: 1120232496 | C3: 王瑞林 | D3: =VLOOKUP([1]成绩单!B3,[1]Sheet1!$A:$K,4,0) -> 精工2311 | E3: 2 | F3: 0.068966 | G3: 89.4679 | H3: 64 | I3: 140 | J3: 0 | K3: 0 | L3: 是 | M3: 2.2 | N3: 6.8 | O3: 14.1 | P3: 10.5 | Q3: 23.35 | S3: =SUM(M3:Q3) -> 56.95 | T3: =COUNTIFS($Y:$Y, Y3, $S:$S, ">"&S3) + 1 -> 1 | U3: =0.85*E3+T3*0.15 -> 1.85 | V3: =100.4-0.4*W3 -> 99.6 | W3: =COUNTIFS($Y:$Y, Y3, $U:$U, "<"&U3) + 1 -> 2 | X3: 29 | Y3: 工业工程
A4: 98 | B4: 1120231274 | C4: 王雨函 | D4: =VLOOKUP([1]成绩单!B4,[1]Sheet1!$A:$K,4,0) -> 精工2310 | E4: 3 | F4: 0.103448 | G4: 89.3982 | H4: 64 | I4: 140 | J4: 0 | K4: 0 | L4: 是 | M4: 1.8 | N4: 1 | O4: 4.3 | P4: 4.7 | Q4: 3.1 | S4: =SUM(M4:Q4) -> 14.9 | T4: =COUNTIFS($Y:$Y, Y4, $S:$S, ">"&S4) + 1 -> 12 | U4: =0.85*E4+T4*0.15 -> 4.35 | V4: =100.4-0.4*W4 -> 99.2 | W4: =COUNTIFS($Y:$Y, Y4, $U:$U, "<"&U4) + 1 -> 3 | X4: 29 | Y4: 工业工程
A5: 99 | B5: 1120232491 | C5: 邱爽 | D5: =VLOOKUP([1]成绩单!B6,[1]Sheet1!$A:$K,4,0) -> 精工2310 | E5: 5 | F5: 0.172414 | G5: 86.6416 | H5: 65 | I5: 143 | J5: 0 | K5: 0 | L5: 是 | M5: 0.2 | N5: 1.5 | O5: 2.3 | P5: 3.5 | Q5: 7.7 | S5: =SUM(M5:Q5) -> 15.2 | T5: =COUNTIFS($Y:$Y, Y5, $S:$S, ">"&S5) + 1 -> 11 | U5: =0.85*E5+T5*0.15 -> 5.9 | V5: =100.4-0.4*W5 -> 98.8 | W5: =COUNTIFS($Y:$Y, Y5, $U:$U, "<"&U5) + 1 -> 4 | X5: 29 | Y5: 工业工程
A6: 100 | B6: 1120231266 | C6: 周小晶 | D6: =VLOOKUP([1]成绩单!B5,[1]Sheet1!$A:$K,4,0) -> 精工2311 | E6: 4 | F6: 0.137931 | G6: 87.9676 | H6: 63 | I6: 139 | J6: 0 | K6: 0 | L6: 是 | M6: 0.56 | N6: 0.3 | O6: 1 | P6: 1.3 | Q6: 5 | S6: =SUM(M6:Q6) -> 8.16 | T6: =COUNTIFS($Y:$Y, Y6, $S:$S, ">"&S6) + 1 -> 18 | U6: =0.85*E6+T6*0.15 -> 6.1 | V6: =100.4-0.4*W6 -> 98.4 | W6: =COUNTIFS($Y:$Y, Y6, $U:$U, "<"&U6) + 1 -> 5 | X6: 29 | Y6: 工业工程
A7: 101 | B7: 1120231446 | C7: 刘繁冶 | D7: =VLOOKUP([1]成绩单!B7,[1]Sheet1!$A:$K,4,0) -> 精工2312 | E7: 6 | F7: 0.206897 | G7: 86.3165 | H7: 63 | I7: 139 | J7: 0 | K7: 0 | L7: 是 | M7: 3.5 | N7: 3.5 | O7: 3.6 | P7: 3.2 | Q7: 8.3 | S7: =SUM(M7:Q7) -> 22.1 | T7: =COUNTIFS($Y:$Y, Y7, $S:$S, ">"&S7) + 1 -> 9 | U7: =0.85*E7+T7*0.15 -> 6.45 | V7: =100.4-0.4*W7 -> 98 | W7: =COUNTIFS($Y:$Y, Y7, $U:$U, "<"&U7) + 1 -> 6 | X7: 29 | Y7: 工业工程
A8: 102 | B8: 1120231653 | C8: 李金霖 | D8: =VLOOKUP([1]成绩单!B8,[1]Sheet1!$A:$K,4,0) -> 精工2313 | E8: 7 | F8: 0.241379 | G8: 86.1968 | H8: 64 | I8: 141 | J8: 0 | K8: 0 | L8: 是 | M8: 2.35 | N8: 3 | O8: 10 | P8: 16 | Q8: 15.4 | S8: =SUM(M8:Q8) -> 46.75 | T8: =COUNTIFS($Y:$Y, Y8, $S:$S, ">"&S8) + 1 -> 4 | U8: =0.85*E8+T8*0.15 -> 6.55 | V8: =100.4-0.4*W8 -> 97.6 | W8: =COUNTIFS($Y:$Y, Y8, $U:$U, "<"&U8) + 1 -> 7 | X8: 29 | Y8: 工业工程
A9: 103 | B9: 1120232492 | C9: 雷濠远 | D9: =VLOOKUP([1]成绩单!B9,[1]Sheet1!$A:$K,4,0) -> 精工2311 | E9: 8 | F9: 0.275862 | G9: 85.5411 | H9: 64 | I9: 140 | J9: 0 | K9: 0 | L9: 是 | M9: 4.4 | N9: 5.9 | O9: 14.5 | P9: 14.9 | Q9: 10.2 | S9: =SUM(M9:Q9) -> 49.9 | T9: =COUNTIFS($Y:$Y, Y9, $S:$S, ">"&S9) + 1 -> 3 | U9: =0.85*E9+T9*0.15 -> 7.25 | V9: =100.4-0.4*W9 -> 97.2 | W9: =COUNTIFS($Y:$Y, Y9, $U:$U, "<"&U9) + 1 -> 8 | X9: 29 | Y9: 工业工程
A10: 104 | B10: 1120231447 | C10: 唐瑞晗 | D10: =VLOOKUP([1]成绩单!B10,[1]Sheet1!$A:$K,4,0) -> 精工2312 | E10: 9 | F10: 0.310345 | G10: 85.4518 | H10: 64 | I10: 140 | J10: 0 | K10: 0 | L10: 是 | M10: 1.9 | N10: 2.7 | O10: 7.5 | P10: 7.18 | Q10: 10.7 | S10: =SUM(M10:Q10) -> 29.98 | T10: =COUNTIFS($Y:$Y, Y10, $S:$S, ">"&S10) + 1 -> 7 | U10: =0.85*E10+T10*0.15 -> 8.7 | V10: =100.4-0.4*W10 -> 96.8 | W10: =COUNTIFS($Y:$Y, Y10, $U:$U, "<"&U10) + 1 -> 9 | X10: 29 | Y10: 工业工程
A11: 105 | B11: 1120231420 | C11: 张家溢 | D11: =VLOOKUP([1]成绩单!B11,[1]Sheet1!$A:$K,4,0) -> 精工2311 | E11: 10 | F11: 0.344828 | G11: 83.9661 | H11: 64 | I11: 140 | J11: 0 | K11: 0 | L11: 是 | M11: 5.4 | N11: 5.8 | O11: 8.1 | P11: 9 | Q11: 13.5 | S11: =SUM(M11:Q11) -> 41.8 | T11: =COUNTIFS($Y:$Y, Y11, $S:$S, ">"&S11) + 1 -> 5 | U11: =0.85*E11+T11*0.15 -> 9.25 | V11: =100.4-0.4*W11 -> 96.4 | W11: =COUNTIFS($Y:$Y, Y11, $U:$U, "<"&U11) + 1 -> 10 | X11: 29 | Y11: 工业工程
A12: 106 | B12: 1120233369 | C12: 吴天宇 | D12: =VLOOKUP([1]成绩单!B12,[1]Sheet1!$A:$K,4,0) -> 精工2312 | E12: 11 | F12: 0.37931 | G12: 83.0142 | H12: 65 | I12: 141.25 | J12: 0 | K12: 0 | L12: 是 | M12: 0.8 | N12: 0.55 | O12: 0.9 | P12: 0.95 | Q12: 6.6 | S12: =SUM(M12:Q12) -> 9.8 | T12: =COUNTIFS($Y:$Y, Y12, $S:$S, ">"&S12) + 1 -> 17 | U12: =0.85*E12+T12*0.15 -> 11.9 | V12: =100.4-0.4*W12 -> 96 | W12: =COUNTIFS($Y:$Y, Y12, $U:$U, "<"&U12) + 1 -> 11 | X12: 29 | Y12: 工业工程
A13: 107 | B13: 1120231317 | C13: 陈彦元 | D13: =VLOOKUP([1]成绩单!B14,[1]Sheet1!$A:$K,4,0) -> 精工2313 | E13: 13 | F13: 0.448276 | G13: 82.2196 | H13: 63 | I13: 140 | J13: 0 | K13: 0 | L13: 是 | M13: 6.5 | N13: 5.74 | O13: 6.3 | P13: 5.3 | Q13: 6.2 | S13: =SUM(M13:Q13) -> 30.04 | T13: =COUNTIFS($Y:$Y, Y13, $S:$S, ">"&S13) + 1 -> 6 | U13: =0.85*E13+T13*0.15 -> 11.95 | V13: =100.4-0.4*W13 -> 95.6 | W13: =COUNTIFS($Y:$Y, Y13, $U:$U, "<"&U13) + 1 -> 12 | X13: 29 | Y13: 工业工程
A14: 108 | B14: 1120233024 | C14: 张明月 | D14: =VLOOKUP([1]成绩单!B13,[1]Sheet1!$A:$K,4,0) -> 精工2313 | E14: 12 | F14: 0.413793 | G14: 82.7021 | H14: 64 | I14: 141 | J14: 1 | K14: 1 | L14: 是 | M14: 0.35 | N14: 1.8 | O14: 3 | P14: 3 | Q14: 3 | S14: =SUM(M14:Q14) -> 11.15 | T14: =COUNTIFS($Y:$Y, Y14, $S:$S, ">"&S14) + 1 -> 13 | U14: =0.85*E14+T14*0.15 -> 12.15 | V14: =100.4-0.4*W14 -> 95.2 | W14: =COUNTIFS($Y:$Y, Y14, $U:$U, "<"&U14) + 1 -> 13 | X14: 29 | Y14: 工业工程
A15: 109 | B15: 1120232209 | C15: 张美鑫 | D15: =VLOOKUP([1]成绩单!B16,[1]Sheet1!$A:$K,4,0) -> 精工2310 | E15: 15 | F15: 0.517241 | G15: 78.9696 | H15: 64 | I15: 140 | J15: 1 | K15: 1 | L15: 是 | M15: 2.4 | N15: 4.4 | O15: 6.3 | P15: 7.8 | Q15: 6.5 | S15: =SUM(M15:Q15) -> 27.4 | T15: =COUNTIFS($Y:$Y, Y15, $S:$S, ">"&S15) + 1 -> 8 | U15: =0.85*E15+T15*0.15 -> 13.95 | V15: =100.4-0.4*W15 -> 94.8 | W15: =COUNTIFS($Y:$Y, Y15, $U:$U, "<"&U15) + 1 -> 14 | X15: 29 | Y15: 工业工程
A16: 110 | B16: 1120232288 | C16: 刘劲菘 | D16: =VLOOKUP([1]成绩单!B15,[1]Sheet1!$A:$K,4,0) -> 精工2311 | E16: 14 | F16: 0.482759 | G16: 80.283 | H16: 65 | I16: 142.25 | J16: 1 | K16: 1 | L16: 是 | M16: 0 | N16: 0.3 | O16: 1.9 | P16: 1.15 | Q16: 1.4 | S16: =SUM(M16:Q16) -> 4.75 | T16: =COUNTIFS($Y:$Y, Y16, $S:$S, ">"&S16) + 1 -> 21 | U16: =0.85*E16+T16*0.15 -> 15.05 | V16: =100.4-0.4*W16 -> 94.4 | W16: =COUNTIFS($Y:$Y, Y16, $U:$U, "<"&U16) + 1 -> 15 | X16: 29 | Y16: 工业工程
A17: 111 | B17: 1120231018 | C17: 袁威 | D17: =VLOOKUP([1]成绩单!B17,[1]Sheet1!$A:$K,4,0) -> 精工2313 | E17: 16 | F17: 0.551724 | G17: 76.7266 | H17: 63 | I17: 139 | J17: 2 | K17: 2 | L17: 是 | M17: 0 | N17: 1.75 | O17: 1 | P17: 1 | Q17: 1 | S17: =SUM(M17:Q17) -> 4.75 | T17: =COUNTIFS($Y:$Y, Y17, $S:$S, ">"&S17) + 1 -> 21 | U17: =0.85*E17+T17*0.15 -> 16.75 | V17: =100.4-0.4*W17 -> 94 | W17: =COUNTIFS($Y:$Y, Y17, $U:$U, "<"&U17) + 1 -> 16 | X17: 29 | Y17: 工业工程
A18: 112 | B18: 1120231418 | C18: 李鹏 | D18: =VLOOKUP([1]成绩单!B19,[1]Sheet1!$A:$K,4,0) -> 精工2311 | E18: 18 | F18: 0.62069 | G18: 75.0414 | H18: 63 | I18: 139 | J18: 1 | K18: 1 | L18: 是 | M18: 3.9 | N18: 5.1 | O18: 0 | P18: 1.4 | Q18: 0 | S18: =SUM(M18:Q18) -> 10.4 | T18: =COUNTIFS($Y:$Y, Y18, $S:$S, ">"&S18) + 1 -> 15 | U18: =0.85*E18+T18*0.15 -> 17.55 | V18: =100.4-0.4*W18 -> 93.6 | W18: =COUNTIFS($Y:$Y, Y18, $U:$U, "<"&U18) + 1 -> 17 | X18: 29 | Y18: 工业工程
A19: 113 | B19: 1120232915 | C19: 李凌杰 | D19: =VLOOKUP([1]成绩单!B18,[1]Sheet1!$A:$K,4,0) -> 精工2311 | E19: 17 | F19: 0.586207 | G19: 76.7156 | H19: 63 | I19: 138 | J19: 1 | K19: 0 | L19: 是 | M19: 0 | N19: 0 | O19: 0 | P19: 0 | Q19: 0 | S19: =SUM(M19:Q19) -> 0 | T19: =COUNTIFS($Y:$Y, Y19, $S:$S, ">"&S19) + 1 -> 24 | U19: =0.85*E19+T19*0.15 -> 18.05 | V19: =100.4-0.4*W19 -> 93.2 | W19: =COUNTIFS($Y:$Y, Y19, $U:$U, "<"&U19) + 1 -> 18 | X19: 29 | Y19: 工业工程
A20: 114 | B20: 1120231013 | C20: 舒妍妍 | D20: =VLOOKUP([1]成绩单!B21,[1]Sheet1!$A:$K,4,0) -> 精工2313 | E20: 20 | F20: 0.689655 | G20: 74.2756 | H20: 66 | I20: 144.25 | J20: 2 | K20: 2 | L20: 是 | M20: 0.5 | N20: -0.175 | O20: 0.55 | P20: 4 | Q20: 0 | S20: =SUM(M20:Q20) -> 4.875 | T20: =COUNTIFS($Y:$Y, Y20, $S:$S, ">"&S20) + 1 -> 20 | U20: =0.85*E20+T20*0.15 -> 20 | V20: =100.4-0.4*W20 -> 92.8 | W20: =COUNTIFS($Y:$Y, Y20, $U:$U, "<"&U20) + 1 -> 19 | X20: 29 | Y20: 工业工程
A21: 115 | B21: 1120234021 | C21: 鄭凱文 | D21: =VLOOKUP([1]成绩单!B23,[1]Sheet1!$A:$K,4,0) -> 精工2312 | E21: 22 | F21: 0.758621 | G21: 69.8282 | H21: 62 | I21: 138.25 | J21: 4 | K21: 2 | L21: 否 | M21: 3.5 | N21: 2.8 | O21: 3.5 | P21: 4.8 | Q21: 1.8 | S21: =SUM(M21:Q21) -> 16.4 | T21: =COUNTIFS($Y:$Y, Y21, $S:$S, ">"&S21) + 1 -> 10 | U21: =0.85*E21+T21*0.15 -> 20.2 | V21: =100.4-0.4*W21 -> 92.4 | W21: =COUNTIFS($Y:$Y, Y21, $U:$U, "<"&U21) + 1 -> 20 | X21: 29 | Y21: 工业工程
A22: 116 | B22: 1120231282 | C22: 刘顺钦 | D22: =VLOOKUP([1]成绩单!B20,[1]Sheet1!$A:$K,4,0) -> 精工2312 | E22: 19 | F22: 0.655172 | G22: 74.8975 | H22: 64 | I22: 139 | J22: 1 | K22: 1 | L22: 是 | M22: 0 | N22: -0.5 | O22: 0 | P22: 0 | Q22: 0 | S22: =SUM(M22:Q22) -> -0.5 | T22: =COUNTIFS($Y:$Y, Y22, $S:$S, ">"&S22) + 1 -> 28 | U22: =0.85*E22+T22*0.15 -> 20.35 | V22: =100.4-0.4*W22 -> 92 | W22: =COUNTIFS($Y:$Y, Y22, $U:$U, "<"&U22) + 1 -> 21 | X22: 29 | Y22: 工业工程
A23: 117 | B23: 1120232212 | C23: 严远昱 | D23: =VLOOKUP([1]成绩单!B22,[1]Sheet1!$A:$K,4,0) -> 精工2310 | E23: 21 | F23: 0.724138 | G23: 73.063 | H23: 60 | I23: 135 | J23: 1 | K23: 0 | L23: 是 | M23: 0.3 | N23: -0.5 | O23: 0 | P23: -1.5 | Q23: 0 | S23: =SUM(M23:Q23) -> -1.7 | T23: =COUNTIFS($Y:$Y, Y23, $S:$S, ">"&S23) + 1 -> 29 | U23: =0.85*E23+T23*0.15 -> 22.2 | V23: =100.4-0.4*W23 -> 91.6 | W23: =COUNTIFS($Y:$Y, Y23, $U:$U, "<"&U23) + 1 -> 22 | X23: 29 | Y23: 工业工程
A24: 118 | B24: 1120232754 | C24: 罗勋康 | D24: =VLOOKUP([1]成绩单!B24,[1]Sheet1!$A:$K,4,0) -> 精工2312 | E24: 23 | F24: 0.793103 | G24: 68.3393 | H24: 64 | I24: 140 | J24: 6 | K24: 3 | L24: 是 | M24: 0 | N24: 3.65 | O24: 0 | P24: -0.5 | Q24: 2.2 | S24: =SUM(M24:Q24) -> 5.35 | T24: =COUNTIFS($Y:$Y, Y24, $S:$S, ">"&S24) + 1 -> 19 | U24: =0.85*E24+T24*0.15 -> 22.4 | V24: =100.4-0.4*W24 -> 91.2 | W24: =COUNTIFS($Y:$Y, Y24, $U:$U, "<"&U24) + 1 -> 23 | X24: 29 | Y24: 工业工程
A25: 119 | B25: 1120231434 | C25: 谢佳铭 | D25: =VLOOKUP([1]成绩单!B25,[1]Sheet1!$A:$K,4,0) -> 精工2312 | E25: 24 | F25: 0.827586 | G25: 67.2196 | H25: 64 | I25: 140 | J25: 4 | K25: 2 | L25: 是 | M25: 1 | N25: 1.3 | O25: 3 | P25: 2 | Q25: 3.5 | S25: =SUM(M25:Q25) -> 10.8 | T25: =COUNTIFS($Y:$Y, Y25, $S:$S, ">"&S25) + 1 -> 14 | U25: =0.85*E25+T25*0.15 -> 22.5 | V25: =100.4-0.4*W25 -> 90.8 | W25: =COUNTIFS($Y:$Y, Y25, $U:$U, "<"&U25) + 1 -> 24 | X25: 29 | Y25: 工业工程
A26: 120 | B26: 1120230740 | C26: 张佳昊 | D26: =VLOOKUP([1]成绩单!B26,[1]Sheet1!$A:$K,4,0) -> 精工2311 | E26: 25 | F26: 0.862069 | G26: 65.991 | H26: 63 | I26: 139 | J26: 6 | K26: 2 | L26: 是 | M26: 0.9 | N26: 1.4 | O26: 0.2 | P26: 0.2 | Q26: 1 | S26: =SUM(M26:Q26) -> 3.7 | T26: =COUNTIFS($Y:$Y, Y26, $S:$S, ">"&S26) + 1 -> 23 | U26: =0.85*E26+T26*0.15 -> 24.7 | V26: =100.4-0.4*W26 -> 90.4 | W26: =COUNTIFS($Y:$Y, Y26, $U:$U, "<"&U26) + 1 -> 25 | X26: 29 | Y26: 工业工程
A27: 121 | B27: 1120222858 | C27: 田雨清 | D27: =VLOOKUP([1]成绩单!B27,[1]Sheet1!$A:$K,4,0) -> 精工2312 | E27: 26 | F27: 0.896552 | G27: 65.6825 | H27: 62 | I27: 137 | J27: 6 | K27: 5 | L27: 是 | M27: 0 | N27: 0 | O27: 0 | P27: 0 | Q27: 0 | S27: =SUM(M27:Q27) -> 0 | T27: =COUNTIFS($Y:$Y, Y27, $S:$S, ">"&S27) + 1 -> 24 | U27: =0.85*E27+T27*0.15 -> 25.7 | V27: =100.4-0.4*W27 -> 90 | W27: =COUNTIFS($Y:$Y, Y27, $U:$U, "<"&U27) + 1 -> 26 | X27: 29 | Y27: 工业工程
A28: 122 | B28: 1120234031 | C28: 郭佳 | D28: =VLOOKUP([1]成绩单!B29,[1]Sheet1!$A:$K,4,0) -> 精工2312 | E28: 28 | F28: 0.965517 | G28: 62.0928 | H28: 61 | I28: 132 | J28: 8 | K28: 2 | L28: 否 | M28: 2.7 | N28: 2.5 | O28: 1.7 | P28: 2.2 | Q28: 1 | S28: =SUM(M28:Q28) -> 10.1 | T28: =COUNTIFS($Y:$Y, Y28, $S:$S, ">"&S28) + 1 -> 16 | U28: =0.85*E28+T28*0.15 -> 26.2 | V28: =100.4-0.4*W28 -> 89.6 | W28: =COUNTIFS($Y:$Y, Y28, $U:$U, "<"&U28) + 1 -> 27 | X28: 29 | Y28: 工业工程
A29: 123 | B29: 1120220682 | C29: 代兵 | D29: =VLOOKUP([1]成绩单!B28,[1]Sheet1!$A:$K,4,0) -> 精工2313 | E29: 27 | F29: 0.931034 | G29: 64.0482 | H29: 63 | I29: 140 | J29: 7 | K29: 6 | L29: 是 | M29: 0 | N29: 0 | O29: 0 | P29: 0 | Q29: 0 | S29: =SUM(M29:Q29) -> 0 | T29: =COUNTIFS($Y:$Y, Y29, $S:$S, ">"&S29) + 1 -> 24 | U29: =0.85*E29+T29*0.15 -> 26.55 | V29: =100.4-0.4*W29 -> 89.2 | W29: =COUNTIFS($Y:$Y, Y29, $U:$U, "<"&U29) + 1 -> 28 | X29: 29 | Y29: 工业工程
A30: 124 | B30: 1120223682 | C30: 范泽暄 | D30: =VLOOKUP([1]成绩单!B30,[1]Sheet1!$A:$K,4,0) -> 精工2310 | E30: 29 | F30: 1 | G30: 57.2161 | H30: 64 | I30: 140 | J30: 12 | K30: 12 | L30: 是 | M30: 0 | N30: 0 | O30: 0 | P30: 0 | Q30: 0 | S30: =SUM(M30:Q30) -> 0 | T30: =COUNTIFS($Y:$Y, Y30, $S:$S, ">"&S30) + 1 -> 24 | U30: =0.85*E30+T30*0.15 -> 28.25 | V30: =100.4-0.4*W30 -> 88.8 | W30: =COUNTIFS($Y:$Y, Y30, $U:$U, "<"&U30) + 1 -> 29 | X30: 29 | Y30: 工业工程

Sheet 机械工程
A1: 序号 | B1: 学号 | C1: 姓名 | D1: 班级 | E1: 课程成绩 本专业名 次 | F1: 课程成绩本 专业排名百 分比 | G1: 课程成绩计算结果 | H1: 纳入计算 的课程数 | I1: 纳入计算课程 获得总学分 | J1: 不及格课 程门数 | K1: 不及格课 程已通过 门数 | L1: 是否通过全 国大学英语 四级 | M1: 第1学期其他表现 | N1: 第2学期其他表现 | O1: 第3学期其他表现 | P1: 第4学期其他表现 | Q1: 第5学期其他表现 | R1: 第6学期其他表现 | S1: 其他表现成绩 | T1: 其他表现 排名名次 | U1: 综合成绩 | V1: 综合 成绩 | W1: 综合排名 名次 | X1: 排名 人数 | Y1: 专业 | Z1: 备注
A2: 125 | B2: 1120230742 | C2: 洪小雨 | D2: =VLOOKUP([1]成绩单!B2,[1]Sheet1!$A:$K,4,0) -> 精工2310 | E2: 1 | F2: 0.011236 | G2: 93.2647 | H2: 60 | I2: 136 | J2: 0 | K2: 0 | L2: 是 | M2: 5 | N2: 5.7 | O2: 7.5 | P2: 14.1 | Q2: 18.3 | S2: =SUM(M2:Q2) -> 50.6 | T2: =COUNTIFS($Y:$Y, Y2, $S:$S, ">"&S2) + 1 -> 4 | U2: =0.85*E2+T2*0.15 -> 1.45 | V2: =100.4-0.4*W2 -> 100 | W2: =COUNTIFS($Y:$Y, Y2, $U:$U, "<"&U2) + 1 -> 1 | X2: 89 | Y2: 机械工程
A3: 126 | B3: 1120231263 | C3: 唐邱扬 | D3: =VLOOKUP([1]成绩单!B4,[1]Sheet1!$A:$K,4,0) -> 精工2310 | E3: 3 | F3: 0.033708 | G3: 92.3346 | H3: 60 | I3: 136 | J3: 0 | K3: 0 | L3: 是 | M3: 4.7 | N3: 5.54 | O3: 17.8 | P3: 20.2 | Q3: 24.9 | S3: =SUM(M3:Q3) -> 73.14 | T3: =COUNTIFS($Y:$Y, Y3, $S:$S, ">"&S3) + 1 -> 3 | U3: =0.85*E3+T3*0.15 -> 3 | V3: =100.4-0.4*W3 -> 99.6 | W3: =COUNTIFS($Y:$Y, Y3, $U:$U, "<"&U3) + 1 -> 2 | X3: 89 | Y3: 机械工程
A4: 127 | B4: 1120233384 | C4: 李宏博 | D4: =VLOOKUP([1]成绩单!B3,[1]Sheet1!$A:$K,4,0) -> 精工2311 | E4: 2 | F4: 0.022472 | G4: 92.4179 | H4: 61 | I4: 137 | J4: 0 | K4: 0 | L4: 是 | M4: 2.8 | N4: 4.2 | O4: 3.7 | P4: 9.8 | Q4: 11.3 | S4: =SUM(M4:Q4) -> 31.8 | T4: =COUNTIFS($Y:$Y, Y4, $S:$S, ">"&S4) + 1 -> 16 | U4: =0.85*E4+T4*0.15 -> 4.1 | V4: =100.4-0.4*W4 -> 99.2 | W4: =COUNTIFS($Y:$Y, Y4, $U:$U, "<"&U4) + 1 -> 3 | X4: 89 | Y4: 机械工程
A5: 128 | B5: 1120232488 | C5: 侯云翔 | D5: =VLOOKUP([1]成绩单!B6,[1]Sheet1!$A:$K,4,0) -> 精工2310 | E5: 5 | F5: 0.05618 | G5: 91.6738 | H5: 63 | I5: 139.5 | J5: 0 | K5: 0 | L5: 是 | M5: 5.8 | N5: 10.2 | O5: 18.4 | P5: 16.8 | Q5: 26.5 | S5: =SUM(M5:Q5) -> 77.7 | T5: =COUNTIFS($Y:$Y, Y5, $S:$S, ">"&S5) + 1 -> 2 | U5: =0.85*E5+T5*0.15 -> 4.55 | V5: =100.4-0.4*W5 -> 98.8 | W5: =COUNTIFS($Y:$Y, Y5, $U:$U, "<"&U5) + 1 -> 4 | X5: 89 | Y5: 机械工程
A6: 129 | B6: 1120232618 | C6: 刘铁彦 | D6: =VLOOKUP([1]成绩单!B7,[1]Sheet1!$A:$K,4,0) -> 精工2312 | E6: 6 | F6: 0.067416 | G6: 91.3214 | H6: 62 | I6: 140 | J6: 0 | K6: 0 | L6: 是 | M6: 8.6 | N6: 7.6 | O6: 31.9 | P6: 14.7 | Q6: 22.05 | S6: =SUM(M6:Q6) -> 84.85 | T6: =COUNTIFS($Y:$Y, Y6, $S:$S, ">"&S6) + 1 -> 1 | U6: =0.85*E6+T6*0.15 -> 5.25 | V6: =100.4-0.4*W6 -> 98.4 | W6: =COUNTIFS($Y:$Y, Y6, $U:$U, "<"&U6) + 1 -> 5 | X6: 89 | Y6: 机械工程
A7: 130 | B7: 1120232901 | C7: 林子扬 | D7: =VLOOKUP([1]成绩单!B5,[1]Sheet1!$A:$K,4,0) -> 精工2311 | E7: 4 | F7: 0.044944 | G7: 92.1606 | H7: 61 | I7: 138.5 | J7: 0 | K7: 0 | L7: 是 | M7: 2.15 | N7: 4.7 | O7: 10.3 | P7: 4.5 | Q7: 10.4 | S7: =SUM(M7:Q7) -> 32.05 | T7: =COUNTIFS($Y:$Y, Y7, $S:$S, ">"&S7) + 1 -> 14 | U7: =0.85*E7+T7*0.15 -> 5.5 | V7: =100.4-0.4*W7 -> 98 | W7: =COUNTIFS($Y:$Y, Y7, $U:$U, "<"&U7) + 1 -> 6 | X7: 89 | Y7: 机械工程
A8: 131 | B8: 1120231847 | C8: 肖凯天 | D8: =VLOOKUP([1]成绩单!B9,[1]Sheet1!$A:$K,4,0) -> 精工2311 | E8: 8 | F8: 0.089888 | G8: 90.6241 | H8: 63 | I8: 141 | J8: 0 | K8: 0 | L8: 是 | M8: 2.7 | N8: 6.2 | O8: 9.8 | P8: 6.2 | Q8: 13.6 | S8: =SUM(M8:Q8) -> 38.5 | T8: =COUNTIFS($Y:$Y, Y8, $S:$S, ">"&S8) + 1 -> 7 | U8: =0.85*E8+T8*0.15 -> 7.85 | V8: =100.4-0.4*W8 -> 97.6 | W8: =COUNTIFS($Y:$Y, Y8, $U:$U, "<"&U8) + 1 -> 7 | X8: 89 | Y8: 机械工程
A9: 132 | B9: 1120232208 | C9: 杜倩荣 | D9: =VLOOKUP([1]成绩单!B11,[1]Sheet1!$A:$K,4,0) -> 精工2311 | E9: 10 | F9: 0.11236 | G9: 90.007 | H9: 64 | I9: 143 | J9: 0 | K9: 0 | L9: 是 | M9: 4.5 | N9: 4.5 | O9: 13.7 | P9: 7.7 | Q9: 11 | S9: =SUM(M9:Q9) -> 41.4 | T9: =COUNTIFS($Y:$Y, Y9, $S:$S, ">"&S9) + 1 -> 6 | U9: =0.85*E9+T9*0.15 -> 9.4 | V9: =100.4-0.4*W9 -> 97.2 | W9: =COUNTIFS($Y:$Y, Y9, $U:$U, "<"&U9) + 1 -> 8 | X9: 89 | Y9: 机械工程
A10: 133 | B10: 1120231444 | C10: 谷沐禹 | D10: =VLOOKUP([1]成绩单!B8,[1]Sheet1!$A:$K,4,0) -> 精工2313 | E10: 7 | F10: 0.078652 | G10: 90.818 | H10: 60 | I10: 136 | J10: 0 | K10: 0 | L10: 是 | M10: 0.4 | N10: 1.5 | O10: 2.6 | P10: 5.4 | Q10: 12.4 | S10: =SUM(M10:Q10) -> 22.3 | T10: =COUNTIFS($Y:$Y, Y10, $S:$S, ">"&S10) + 1 -> 30 | U10: =0.85*E10+T10*0.15 -> 10.45 | V10: =100.4-0.4*W10 -> 96.8 | W10: =COUNTIFS($Y:$Y, Y10, $U:$U, "<"&U10) + 1 -> 9 | X10: 89 | Y10: 机械工程
A11: 134 | B11: 1120231430 | C11: 朱海 | D11: =VLOOKUP([1]成绩单!B12,[1]Sheet1!$A:$K,4,0) -> 精工2312 | E11: 11 | F11: 0.123596 | G11: 89.9069 | H11: 61 | I11: 137 | J11: 0 | K11: 0 | L11: 是 | M11: 5.5 | N11: 8.7 | O11: 3.5 | P11: 7.4 | Q11: 12.3 | S11: =SUM(M11:Q11) -> 37.4 | T11: =COUNTIFS($Y:$Y, Y11, $S:$S, ">"&S11) + 1 -> 8 | U11: =0.85*E11+T11*0.15 -> 10.55 | V11: =100.4-0.4*W11 -> 96.4 | W11: =COUNTIFS($Y:$Y, Y11, $U:$U, "<"&U11) + 1 -> 10 | X11: 89 | Y11: 机械工程
A12: 135 | B12: 1120231772 | C12: 贾智翔 | D12: =VLOOKUP([1]成绩单!B10,[1]Sheet1!$A:$K,4,0) -> 精工2312 | E12: 9 | F12: 0.101124 | G12: 90.5199 | H12: 62 | I12: 138 | J12: 0 | K12: 0 | L12: 是 | M12: 0.9 | N12: 6.7 | O12: 5.8 | P12: 3.5 | Q12: 12.5 | S12: =SUM(M12:Q12) -> 29.4 | T12: =COUNTIFS($Y:$Y, Y12, $S:$S, ">"&S12) + 1 -> 21 | U12: =0.85*E12+T12*0.15 -> 10.8 | V12: =100.4-0.4*W12 -> 96 | W12: =COUNTIFS($Y:$Y, Y12, $U:$U, "<"&U12) + 1 -> 11 | X12: 89 | Y12: 机械工程
A13: 136 | B13: 1120231023 | C13: 杨禹皓 | D13: =VLOOKUP([1]成绩单!B14,[1]Sheet1!$A:$K,4,0) -> 精工2313 | E13: 13 | F13: 0.146067 | G13: 89.4051 | H13: 61 | I13: 137 | J13: 0 | K13: 0 | L13: 是 | M13: 2.5 | N13: 4.3 | O13: 4.4 | P13: 4 | Q13: 7.3 | S13: =SUM(M13:Q13) -> 22.5 | T13: =COUNTIFS($Y:$Y, Y13, $S:$S, ">"&S13) + 1 -> 29 | U13: =0.85*E13+T13*0.15 -> 15.4 | V13: =100.4-0.4*W13 -> 95.6 | W13: =COUNTIFS($Y:$Y, Y13, $U:$U, "<"&U13) + 1 -> 12 | X13: 89 | Y13: 机械工程
A14: 137 | B14: 1120230335 | C14: 肖文博 | D14: =VLOOKUP([1]成绩单!B13,[1]Sheet1!$A:$K,4,0) -> 精工2313 | E14: 12 | F14: 0.134831 | G14: 89.4761 | H14: 61 | I14: 136 | J14: 0 | K14: 0 | L14: 是 | M14: 2 | N14: 3.2 | O14: 4.8 | P14: 8 | Q14: 2.9 | S14: =SUM(M14:Q14) -> 20.9 | T14: =COUNTIFS($Y:$Y, Y14, $S:$S, ">"&S14) + 1 -> 35 | U14: =0.85*E14+T14*0.15 -> 15.45 | V14: =100.4-0.4*W14 -> 95.2 | W14: =COUNTIFS($Y:$Y, Y14, $U:$U, "<"&U14) + 1 -> 13 | X14: 89 | Y14: 机械工程
A15: 138 | B15: 1120232611 | C15: 邹元杰 | D15: =VLOOKUP([1]成绩单!B16,[1]Sheet1!$A:$K,4,0) -> 精工2310 | E15: 15 | F15: 0.168539 | G15: 88.6107 | H15: 65 | I15: 144.5 | J15: 0 | K15: 0 | L15: 是 | M15: 0.2 | N15: 0.95 | O15: 10 | P15: 6.75 | Q15: 5.7 | S15: =SUM(M15:Q15) -> 23.6 | T15: =COUNTIFS($Y:$Y, Y15, $S:$S, ">"&S15) + 1 -> 27 | U15: =0.85*E15+T15*0.15 -> 16.8 | V15: =100.4-0.4*W15 -> 94.8 | W15: =COUNTIFS($Y:$Y, Y15, $U:$U, "<"&U15) + 1 -> 14 | X15: 89 | Y15: 机械工程
A16: 139 | B16: 1120230324 | C16: 刘俊雄 | D16: =VLOOKUP([1]成绩单!B17,[1]Sheet1!$A:$K,4,0) -> 精工2313 | E16: 16 | F16: 0.179775 | G16: 88.5702 | H16: 64 | I16: 142.5 | J16: 0 | K16: 0 | L16: 是 | M16: 2 | N16: 4.9 | O16: 3.3 | P16: 9.9 | Q16: 6.4 | S16: =SUM(M16:Q16) -> 26.5 | T16: =COUNTIFS($Y:$Y, Y16, $S:$S, ">"&S16) + 1 -> 24 | U16: =0.85*E16+T16*0.15 -> 17.2 | V16: =100.4-0.4*W16 -> 94.4 | W16: =COUNTIFS($Y:$Y, Y16, $U:$U, "<"&U16) + 1 -> 15 | X16: 89 | Y16: 机械工程
A17: 140 | B17: 1120232887 | C17: 唐明旭 | D17: =VLOOKUP([1]成绩单!B15,[1]Sheet1!$A:$K,4,0) -> 精工2311 | E17: 14 | F17: 0.157303 | G17: 89.2978 | H17: 60 | I17: 136 | J17: 0 | K17: 0 | L17: 是 | M17: 1 | N17: 1.5 | O17: 2.825 | P17: 5.8 | Q17: 8.55 | S17: =SUM(M17:Q17) -> 19.675 | T17: =COUNTIFS($Y:$Y, Y17, $S:$S, ">"&S17) + 1 -> 36 | U17: =0.85*E17+T17*0.15 -> 17.3 | V17: =100.4-0.4*W17 -> 94 | W17: =COUNTIFS($Y:$Y, Y17, $U:$U, "<"&U17) + 1 -> 16 | X17: 89 | Y17: 机械工程
A18: 141 | B18: 1120230374 | C18: 韦颉 | D18: =VLOOKUP([1]成绩单!B19,[1]Sheet1!$A:$K,4,0) -> 精工2311 | E18: 18 | F18: 0.202247 | G18: 88.1203 | H18: 66 | I18: 147.5 | J18: 0 | K18: 0 | L18: 是 | M18: 1.9 | N18: 1 | O18: 7.3 | P18: 5.3 | Q18: 16.4 | S18: =SUM(M18:Q18) -> 31.9 | T18: =COUNTIFS($Y:$Y, Y18, $S:$S, ">"&S18) + 1 -> 15 | U18: =0.85*E18+T18*0.15 -> 17.55 | V18: =100.4-0.4*W18 -> 93.6 | W18: =COUNTIFS($Y:$Y, Y18, $U:$U, "<"&U18) + 1 -> 17 | X18: 89 | Y18: 机械工程
A19: 142 | B19: 1120231401 | C19: 崔庆瞻 | D19: =VLOOKUP([1]成绩单!B20,[1]Sheet1!$A:$K,4,0) -> 精工2312 | E19: 19 | F19: 0.213483 | G19: 88.0864 | H19: 61 | I19: 136 | J19: 0 | K19: 0 | L19: 是 | M19: 1.7 | N19: 2.94 | O19: 9 | P19: 5.5 | Q19: 11 | S19: =SUM(M19:Q19) -> 30.14 | T19: =COUNTIFS($Y:$Y, Y19, $S:$S, ">"&S19) + 1 -> 17 | U19: =0.85*E19+T19*0.15 -> 18.7 | V19: =100.4-0.4*W19 -> 93.2 | W19: =COUNTIFS($Y:$Y, Y19, $U:$U, "<"&U19) + 1 -> 18 | X19: 89 | Y19: 机械工程
A20: 143 | B20: 1120233001 | C20: 李夏雨 | D20: =VLOOKUP([1]成绩单!B21,[1]Sheet1!$A:$K,4,0) -> 精工2313 | E20: 20 | F20: 0.224719 | G20: 88.0717 | H20: 60 | I20: 136 | J20: 0 | K20: 0 | L20: 是 | M20: 3.2 | N20: 2.2 | O20: 7 | P20: 10.7 | Q20: 10.34 | S20: =SUM(M20:Q20) -> 33.44 | T20: =COUNTIFS($Y:$Y, Y20, $S:$S, ">"&S20) + 1 -> 12 | U20: =0.85*E20+T20*0.15 -> 18.8 | V20: =100.4-0.4*W20 -> 92.8 | W20: =COUNTIFS($Y:$Y, Y20, $U:$U, "<"&U20) + 1 -> 19 | X20: 89 | Y20: 机械工程
A21: 144 | B21: 1120231281 | C21: 韦迎新 | D21: =VLOOKUP([1]成绩单!B22,[1]Sheet1!$A:$K,4,0) -> 精工2310 | E21: 21 | F21: 0.235955 | G21: 87.9456 | H21: 66 | I21: 147 | J21: 0 | K21: 0 | L21: 是 | M21: 1.5 | N21: 2 | O21: 4 | P21: 9 | Q21: 17.2 | S21: =SUM(M21:Q21) -> 33.7 | T21: =COUNTIFS($Y:$Y, Y21, $S:$S, ">"&S21) + 1 -> 11 | U21: =0.85*E21+T21*0.15 -> 19.5 | V21: =100.4-0.4*W21 -> 92.4 | W21: =COUNTIFS($Y:$Y, Y21, $U:$U, "<"&U21) + 1 -> 20 | X21: 89 | Y21: 机械工程
A22: 145 | B22: 1120231007 | C22: 熊世宸 | D22: =VLOOKUP([1]成绩单!B18,[1]Sheet1!$A:$K,4,0) -> 精工2311 | E22: 17 | F22: 0.191011 | G22: 88.1697 | H22: 61 | I22: 137 | J22: 0 | K22: 0 | L22: 是 | M22: 2.75 | N22: 3.15 | O22: 5.2 | P22: 1.7 | Q22: 5.25 | S22: =SUM(M22:Q22) -> 18.05 | T22: =COUNTIFS($Y:$Y, Y22, $S:$S, ">"&S22) + 1 -> 39 | U22: =0.85*E22+T22*0.15 -> 20.3 | V22: =100.4-0.4*W22 -> 92 | W22: =COUNTIFS($Y:$Y, Y22, $U:$U, "<"&U22) + 1 -> 21 | X22: 89 | Y22: 机械工程
A23: 146 | B23: 1120231262 | C23: 夏琪淇 | D23: =VLOOKUP([1]成绩单!B24,[1]Sheet1!$A:$K,4,0) -> 精工2312 | E23: 23 | F23: 0.258427 | G23: 87.5804 | H23: 64 | I23: 143 | J23: 0 | K23: 0 | L23: 是 | M23: 5.3 | N23: 5.4 | O23: 10.1 | P23: 8.7 | Q23: 12.9 | S23: =SUM(M23:Q23) -> 42.4 | T23: =COUNTIFS($Y:$Y, Y23, $S:$S, ">"&S23) + 1 -> 5 | U23: =0.85*E23+T23*0.15 -> 20.3 | V23: =100.4-0.4*W23 -> 92 | W23: =COUNTIFS($Y:$Y, Y23, $U:$U, "<"&U23) + 1 -> 21 | X23: 89 | Y23: 机械工程
A24: 147 | B24: 1120231008 | C24: 段练 | D24: =VLOOKUP([1]成绩单!B25,[1]Sheet1!$A:$K,4,0) -> 精工2312 | E24: 24 | F24: 0.269663 | G24: 87.5639 | H24: 61 | I24: 137 | J24: 0 | K24: 0 | L24: 是 | M24: 4.15 | N24: 9 | O24: 6 | P24: 4.2 | Q24: 13.5 | S24: =SUM(M24:Q24) -> 36.85 | T24: =COUNTIFS($Y:$Y, Y24, $S:$S, ">"&S24) + 1 -> 9 | U24: =0.85*E24+T24*0.15 -> 21.75 | V24: =100.4-0.4*W24 -> 91.2 | W24: =COUNTIFS($Y:$Y, Y24, $U:$U, "<"&U24) + 1 -> 23 | X24: 89 | Y24: 机械工程
A25: 148 | B25: 1120231265 | C25: 杨子萱 | D25: =VLOOKUP([1]成绩单!B28,[1]Sheet1!$A:$K,4,0) -> 精工2313 | E25: 27 | F25: 0.303371 | G25: 87.3869 | H25: 62 | I25: 137 | J25: 0 | K25: 0 | L25: 是 | M25: 2.3 | N25: 4.2 | O25: 7.7 | P25: 6.5 | Q25: 8.9 | S25: =SUM(M25:Q25) -> 29.6 | T25: =COUNTIFS($Y:$Y, Y25, $S:$S, ">"&S25) + 1 -> 20 | U25: =0.85*E25+T25*0.15 -> 25.95 | V25: =100.4-0.4*W25 -> 90.8 | W25: =COUNTIFS($Y:$Y, Y25, $U:$U, "<"&U25) + 1 -> 24 | X25: 89 | Y25: 机械工程
A26: 149 | B26: 1120230990 | C26: 李在天 | D26: =VLOOKUP([1]成绩单!B26,[1]Sheet1!$A:$K,4,0) -> 精工2311 | E26: 25 | F26: 0.280899 | G26: 87.5475 | H26: 63 | I26: 142 | J26: 0 | K26: 0 | L26: 是 | M26: 3.6 | N26: 1.5 | O26: 2 | P26: 4.6 | Q26: 6.8 | S26: =SUM(M26:Q26) -> 18.5 | T26: =COUNTIFS($Y:$Y, Y26, $S:$S, ">"&S26) + 1 -> 37 | U26: =0.85*E26+T26*0.15 -> 26.8 | V26: =100.4-0.4*W26 -> 90.4 | W26: =COUNTIFS($Y:$Y, Y26, $U:$U, "<"&U26) + 1 -> 25 | X26: 89 | Y26: 机械工程
A27: 150 | B27: 1120231746 | C27: 赵奕智 | D27: =VLOOKUP([1]成绩单!B23,[1]Sheet1!$A:$K,4,0) -> 精工2312 | E27: 22 | F27: 0.247191 | G27: 87.801 | H27: 68 | I27: 147 | J27: 0 | K27: 0 | L27: 是 | M27: 2.1 | N27: 2.2 | O27: 1.3 | P27: 2.5 | Q27: 1.5 | S27: =SUM(M27:Q27) -> 9.6 | T27: =COUNTIFS($Y:$Y, Y27, $S:$S, ">"&S27) + 1 -> 55 | U27: =0.85*E27+T27*0.15 -> 26.95 | V27: =100.4-0.4*W27 -> 90 | W27: =COUNTIFS($Y:$Y, Y27, $U:$U, "<"&U27) + 1 -> 26 | X27: 89 | Y27: 机械工程
A28: 151 | B28: 1120232468 | C28: 周峻羽 | D28: =VLOOKUP([1]成绩单!B29,[1]Sheet1!$A:$K,4,0) -> 精工2312 | E28: 28 | F28: 0.314607 | G28: 87.3419 | H28: 60 | I28: 136 | J28: 0 | K28: 0 | L28: 是 | M28: 4 | N28: 7 | O28: 3.8 | P28: 6.7 | Q28: 4.2 | S28: =SUM(M28:Q28) -> 25.7 | T28: =COUNTIFS($Y:$Y, Y28, $S:$S, ">"&S28) + 1 -> 25 | U28: =0.85*E28+T28*0.15 -> 27.55 | V28: =100.4-0.4*W28 -> 89.6 | W28: =COUNTIFS($Y:$Y, Y28, $U:$U, "<"&U28) + 1 -> 27 | X28: 89 | Y28: 机械工程
A29: 152 | B29: 1120232626 | C29: 汪品 | D29: =VLOOKUP([1]成绩单!B27,[1]Sheet1!$A:$K,4,0) -> 精工2312 | E29: 26 | F29: 0.292135 | G29: 87.4099 | H29: 60 | I29: 136 | J29: 0 | K29: 0 | L29: 是 | M29: 0.45 | N29: 2 | O29: 0 | P29: 0.5 | Q29: 0.5 | S29: =SUM(M29:Q29) -> 3.45 | T29: =COUNTIFS($Y:$Y, Y29, $S:$S, ">"&S29) + 1 -> 75 | U29: =0.85*E29+T29*0.15 -> 33.35 | V29: =100.4-0.4*W29 -> 89.2 | W29: =COUNTIFS($Y:$Y, Y29, $U:$U, "<"&U29) + 1 -> 28 | X29: 89 | Y29: 机械工程
A30: 153 | B30: 1120231633 | C30: 罗仁健 | D30: =VLOOKUP([1]成绩单!B34,[1]Sheet1!$A:$K,4,0) -> 精工2310 | E30: 33 | F30: 0.370787 | G30: 86.4485 | H30: 60 | I30: 136 | J30: 0 | K30: 0 | L30: 是 | M30: 2.3 | N30: 1.85 | O30: 2.3 | P30: 3.6 | Q30: 7.6 | S30: =SUM(M30:Q30) -> 17.65 | T30: =COUNTIFS($Y:$Y, Y30, $S:$S, ">"&S30) + 1 -> 40 | U30: =0.85*E30+T30*0.15 -> 34.05 | V30: =100.4-0.4*W30 -> 88.8 | W30: =COUNTIFS($Y:$Y, Y30, $U:$U, "<"&U30) + 1 -> 29 | X30: 89 | Y30: 机械工程
A31: 154 | B31: 1120231027 | C31: 戴隆煊 | D31: =VLOOKUP([1]成绩单!B30,[1]Sheet1!$A:$K,4,0) -> 精工2310 | E31: 29 | F31: 0.325843 | G31: 87.2896 | H31: 62 | I31: 139 | J31: 0 | K31: 0 | L31: 是 | M31: 1.3 | N31: 1 | O31: 1.65 | P31: 1.05 | Q31: 2 | S31: =SUM(M31:Q31) -> 7 | T31: =COUNTIFS($Y:$Y, Y31, $S:$S, ">"&S31) + 1 -> 63 | U31: =0.85*E31+T31*0.15 -> 34.1 | V31: =100.4-0.4*W31 -> 88.4 | W31: =COUNTIFS($Y:$Y, Y31, $U:$U, "<"&U31) + 1 -> 30 | X31: 89 | Y31: 机械工程
A32: 155 | B32: 1120232487 | C32: 王镜然 | D32: =VLOOKUP([1]成绩单!B36,[1]Sheet1!$A:$K,4,0) -> 精工2311 | E32: 35 | F32: 0.393258 | G32: 86.3292 | H32: 63 | I32: 142 | J32: 0 | K32: 0 | L32: 是 | M32: 4 | N32: 3.3 | O32: 3.8 | P32: 3.5 | Q32: 6.5 | S32: =SUM(M32:Q32) -> 21.1 | T32: =COUNTIFS($Y:$Y, Y32, $S:$S, ">"&S32) + 1 -> 34 | U32: =0.85*E32+T32*0.15 -> 34.85 | V32: =100.4-0.4*W32 -> 88 | W32: =COUNTIFS($Y:$Y, Y32, $U:$U, "<"&U32) + 1 -> 31 | X32: 89 | Y32: 机械工程
A33: 156 | B33: 1120232314 | C33: 桑春月 | D33: =VLOOKUP([1]成绩单!B39,[1]Sheet1!$A:$K,4,0) -> 精工2310 | E33: 38 | F33: 0.426966 | G33: 85.4489 | H33: 63 | I33: 142 | J33: 0 | K33: 0 | L33: 是 | M33: 3.3 | N33: 5.6 | O33: 8.8 | P33: 10.2 | Q33: 2 | S33: =SUM(M33:Q33) -> 29.9 | T33: =COUNTIFS($Y:$Y, Y33, $S:$S, ">"&S33) + 1 -> 19 | U33: =0.85*E33+T33*0.15 -> 35.15 | V33: =100.4-0.4*W33 -> 87.6 | W33: =COUNTIFS($Y:$Y, Y33, $U:$U, "<"&U33) + 1 -> 32 | X33: 89 | Y33: 机械工程
A34: 157 | B34: 1120232517 | C34: 梁靖旭 | D34: =VLOOKUP([1]成绩单!B32,[1]Sheet1!$A:$K,4,0) -> 精工2310 | E34: 31 | F34: 0.348315 | G34: 86.836 | H34: 64 | I34: 141.75 | J34: 0 | K34: 0 | L34: 是 | M34: 1 | N34: 1.6 | O34: 1.8 | P34: 1 | Q34: 2.5 | S34: =SUM(M34:Q34) -> 7.9 | T34: =COUNTIFS($Y:$Y, Y34, $S:$S, ">"&S34) + 1 -> 61 | U34: =0.85*E34+T34*0.15 -> 35.5 | V34: =100.4-0.4*W34 -> 87.2 | W34: =COUNTIFS($Y:$Y, Y34, $U:$U, "<"&U34) + 1 -> 33 | X34: 89 | Y34: 机械工程
A35: 158 | B35: 1120231756 | C35: 司常锐 | D35: =VLOOKUP([1]成绩单!B35,[1]Sheet1!$A:$K,4,0) -> 精工2310 | E35: 34 | F35: 0.382022 | G35: 86.414 | H35: 63 | I35: 139.5 | J35: 0 | K35: 0 | L35: 是 | M35: 3.5 | N35: 2.6 | O35: 2.7 | P35: 1.8 | Q35: 2.7 | S35: =SUM(M35:Q35) -> 13.3 | T35: =COUNTIFS($Y:$Y, Y35, $S:$S, ">"&S35) + 1 -> 48 | U35: =0.85*E35+T35*0.15 -> 36.1 | V35: =100.4-0.4*W35 -> 86.8 | W35: =COUNTIFS($Y:$Y, Y35, $U:$U, "<"&U35) + 1 -> 34 | X35: 89 | Y35: 机械工程
A36: 159 | B36: 1120231292 | C36: 夏智豪 | D36: =VLOOKUP([1]成绩单!B42,[1]Sheet1!$A:$K,4,0) -> 精工2310 | E36: 41 | F36: 0.460674 | G36: 84.6486 | H36: 64 | I36: 143 | J36: 0 | K36: 0 | L36: 是 | M36: 3.65 | N36: 6.275 | O36: 4.5 | P36: 3 | Q36: 14.9 | S36: =SUM(M36:Q36) -> 32.325 | T36: =COUNTIFS($Y:$Y, Y36, $S:$S, ">"&S36) + 1 -> 13 | U36: =0.85*E36+T36*0.15 -> 36.8 | V36: =100.4-0.4*W36 -> 86.4 | W36: =COUNTIFS($Y:$Y, Y36, $U:$U, "<"&U36) + 1 -> 35 | X36: 89 | Y36: 机械工程
A37: 160 | B37: 1120230354 | C37: 单子聪 | D37: =VLOOKUP([1]成绩单!B31,[1]Sheet1!$A:$K,4,0) -> 精工2313 | E37: 30 | F37: 0.337079 | G37: 87.0052 | H37: 62 | I37: 143.5 | J37: 0 | K37: 0 | L37: 是 | M37: 0 | N37: 0 | O37: 0 | P37: 0 | Q37: 0 | S37: =SUM(M37:Q37) -> 0 | T37: =COUNTIFS($Y:$Y, Y37, $S:$S, ">"&S37) + 1 -> 84 | U37: =0.85*E37+T37*0.15 -> 38.1 | V37: =100.4-0.4*W37 -> 86 | W37: =COUNTIFS($Y:$Y, Y37, $U:$U, "<"&U37) + 1 -> 36 | X37: 89 | Y37: 机械工程
A38: 161 | B38: 1120231754 | C38: 喻韬 | D38: =VLOOKUP([1]成绩单!B33,[1]Sheet1!$A:$K,4,0) -> 精工2312 | E38: 32 | F38: 0.359551 | G38: 86.7422 | H38: 63 | I38: 136.75 | J38: 0 | K38: 0 | L38: 是 | M38: 1.3 | N38: 0 | O38: 0 | P38: 0 | Q38: 2.9 | S38: =SUM(M38:Q38) -> 4.2 | T38: =COUNTIFS($Y:$Y, Y38, $S:$S, ">"&S38) + 1 -> 73 | U38: =0.85*E38+T38*0.15 -> 38.15 | V38: =100.4-0.4*W38 -> 85.6 | W38: =COUNTIFS($Y:$Y, Y38, $U:$U, "<"&U38) + 1 -> 37 | X38: 89 | Y38: 机械工程
A39: 162 | B39: 1120231021 | C39: 曾越 | D39: =VLOOKUP([1]成绩单!B37,[1]Sheet1!$A:$K,4,0) -> 精工2313 | E39: 36 | F39: 0.404494 | G39: 86.3235 | H39: 60 | I39: 136 | J39: 0 | K39: 0 | L39: 是 | M39: 1 | N39: 1 | O39: 3 | P39: 4.2 | Q39: 1 | S39: =SUM(M39:Q39) -> 10.2 | T39: =COUNTIFS($Y:$Y, Y39, $S:$S, ">"&S39) + 1 -> 53 | U39: =0.85*E39+T39*0.15 -> 38.55 | V39: =100.4-0.4*W39 -> 85.2 | W39: =COUNTIFS($Y:$Y, Y39, $U:$U, "<"&U39) + 1 -> 38 | X39: 89 | Y39: 机械工程
A40: 163 | B40: 1120232039 | C40: 王一鸣 | D40: =VLOOKUP([1]成绩单!B40,[1]Sheet1!$A:$K,4,0) -> 精工2312 | E40: 39 | F40: 0.438202 | G40: 85.1282 | H40: 62 | I40: 138.5 | J40: 0 | K40: 0 | L40: 是 | M40: 3.7 | N40: 2.2 | O40: 1.7 | P40: 1.5 | Q40: 0.2 | S40: =SUM(M40:Q40) -> 9.3 | T40: =COUNTIFS($Y:$Y, Y40, $S:$S, ">"&S40) + 1 -> 56 | U40: =0.85*E40+T40*0.15 -> 41.55 | V40: =100.4-0.4*W40 -> 84.8 | W40: =COUNTIFS($Y:$Y, Y40, $U:$U, "<"&U40) + 1 -> 39 | X40: 89 | Y40: 机械工程
...

Sheet 能源与动力工程
A1: 序号 | B1: 学号 | C1: 姓名 | D1: 班级 | E1: 课程成绩 本专业名 次 | F1: 课程成绩本 专业排名百 分比 | G1: 课程成绩计算结果 | H1: 纳入计算 的课程数 | I1: 纳入计算课程 获得总学分 | J1: 不及格课 程门数 | K1: 不及格课 程已通过 门数 | L1: 是否通过全 国大学英语 四级 | M1: 第1学期其他表现 | N1: 第2学期其他表现 | O1: 第3学期其他表现 | P1: 第4学期其他表现 | Q1: 第5学期其他表现 | R1: 第6学期其他表现 | S1: 其他表现成绩 | T1: 其他表现 排名名次 | U1: 综合成绩 | V1: 综合 成绩 | W1: 综合排名 名次 | X1: 排名 人数 | Y1: 专业 | Z1: 备注
A2: 227 | B2: 1120232224 | C2: 胡文政 | D2: =VLOOKUP([1]成绩单!B3,[1]Sheet1!$A:$K,4,0) -> 精工2311 | E2: 2 | F2: 0.03125 | G2: 90.3921 | H2: 61 | I2: 139 | J2: 0 | K2: 0 | L2: 是 | M2: 1.95 | N2: 1 | O2: 5 | P2: 7.2 | Q2: 9.8 | S2: =SUM(M2:Q2) -> 24.95 | T2: =COUNTIFS($Y:$Y, Y2, $S:$S, ">"&S2) + 1 -> 11 | U2: =0.85*E2+T2*0.15 -> 3.35 | V2: =100.4-0.4*W2 -> 100 | W2: =COUNTIFS($Y:$Y, Y2, $U:$U, "<"&U2) + 1 -> 1 | X2: 64 | Y2: 能源与动力工程
A3: 228 | B3: 1120232762 | C3: 廖方瑛 | D3: =VLOOKUP([1]成绩单!B5,[1]Sheet1!$A:$K,4,0) -> 精工2311 | E3: 4 | F3: 0.0625 | G3: 88.1556 | H3: 68 | I3: 151 | J3: 1 | K3: 1 | L3: 是 | M3: 2.95 | N3: 3.5 | O3: 13 | P3: 6.7 | Q3: 11.3 | S3: =SUM(M3:Q3) -> 37.45 | T3: =COUNTIFS($Y:$Y, Y3, $S:$S, ">"&S3) + 1 -> 2 | U3: =0.85*E3+T3*0.15 -> 3.7 | V3: =100.4-0.4*W3 -> 99.6 | W3: =COUNTIFS($Y:$Y, Y3, $U:$U, "<"&U3) + 1 -> 2 | X3: 64 | Y3: 能源与动力工程
A4: 229 | B4: 1120230820 | C4: 张哲源 | D4: =VLOOKUP([1]成绩单!B4,[1]Sheet1!$A:$K,4,0) -> 精工2310 | E4: 3 | F4: 0.046875 | G4: 89.6481 | H4: 63 | I4: 139.25 | J4: 0 | K4: 0 | L4: 是 | M4: 1.75 | N4: 2.6 | O4: 5.5 | P4: 8.5 | Q4: 6 | S4: =SUM(M4:Q4) -> 24.35 | T4: =COUNTIFS($Y:$Y, Y4, $S:$S, ">"&S4) + 1 -> 13 | U4: =0.85*E4+T4*0.15 -> 4.5 | V4: =100.4-0.4*W4 -> 99.2 | W4: =COUNTIFS($Y:$Y, Y4, $U:$U, "<"&U4) + 1 -> 3 | X4: 64 | Y4: 能源与动力工程
A5: 230 | B5: 1120232494 | C5: 纳旭辉 | D5: =VLOOKUP([1]成绩单!B7,[1]Sheet1!$A:$K,4,0) -> 精工2312 | E5: 6 | F5: 0.09375 | G5: 87.633 | H5: 62 | I5: 141 | J5: 0 | K5: 0 | L5: 是 | M5: 3.8 | N5: 2 | O5: 9.1 | P5: 6.6 | Q5: 7 | S5: =SUM(M5:Q5) -> 28.5 | T5: =COUNTIFS($Y:$Y, Y5, $S:$S, ">"&S5) + 1 -> 8 | U5: =0.85*E5+T5*0.15 -> 6.3 | V5: =100.4-0.4*W5 -> 98.8 | W5: =COUNTIFS($Y:$Y, Y5, $U:$U, "<"&U5) + 1 -> 4 | X5: 64 | Y5: 能源与动力工程
A6: 231 | B6: 1120230992 | C6: 上官文超 | D6: =VLOOKUP([1]成绩单!B2,[1]Sheet1!$A:$K,4,0) -> 精工2310 | E6: 1 | F6: 0.015625 | G6: 90.5279 | H6: 70 | I6: 152.5 | J6: 0 | K6: 0 | L6: 是 | M6: 2.1 | N6: 0 | O6: 0.8 | P6: 1 | Q6: 0 | S6: =SUM(M6:Q6) -> 3.9 | T6: =COUNTIFS($Y:$Y, Y6, $S:$S, ">"&S6) + 1 -> 41 | U6: =0.85*E6+T6*0.15 -> 7 | V6: =100.4-0.4*W6 -> 98.4 | W6: =COUNTIFS($Y:$Y, Y6, $U:$U, "<"&U6) + 1 -> 5 | X6: 64 | Y6: 能源与动力工程
A7: 232 | B7: 1120231419 | C7: 沈红博 | D7: =VLOOKUP([1]成绩单!B9,[1]Sheet1!$A:$K,4,0) -> 精工2311 | E7: 8 | F7: 0.125 | G7: 87.0912 | H7: 68 | I7: 148 | J7: 0 | K7: 0 | L7: 是 | M7: 4.1 | N7: 4 | O7: 4.5 | P7: 5.5 | Q7: 8.3 | S7: =SUM(M7:Q7) -> 26.4 | T7: =COUNTIFS($Y:$Y, Y7, $S:$S, ">"&S7) + 1 -> 10 | U7: =0.85*E7+T7*0.15 -> 8.3 | V7: =100.4-0.4*W7 -> 98 | W7: =COUNTIFS($Y:$Y, Y7, $U:$U, "<"&U7) + 1 -> 6 | X7: 64 | Y7: 能源与动力工程
A8: 233 | B8: 1120230363 | C8: 匡锐 | D8: =VLOOKUP([1]成绩单!B6,[1]Sheet1!$A:$K,4,0) -> 精工2310 | E8: 5 | F8: 0.078125 | G8: 87.764 | H8: 64 | I8: 143 | J8: 0 | K8: 0 | L8: 是 | M8: 2.1 | N8: 0.85 | O8: 1 | P8: 1 | Q8: 0 | S8: =SUM(M8:Q8) -> 4.95 | T8: =COUNTIFS($Y:$Y, Y8, $S:$S, ">"&S8) + 1 -> 37 | U8: =0.85*E8+T8*0.15 -> 9.8 | V8: =100.4-0.4*W8 -> 97.6 | W8: =COUNTIFS($Y:$Y, Y8, $U:$U, "<"&U8) + 1 -> 7 | X8: 64 | Y8: 能源与动力工程
A9: 234 | B9: 1120232902 | C9: 袁天泽 | D9: =VLOOKUP([1]成绩单!B11,[1]Sheet1!$A:$K,4,0) -> 精工2311 | E9: 10 | F9: 0.15625 | G9: 86.7609 | H9: 67 | I9: 149.5 | J9: 0 | K9: 0 | L9: 是 | M9: 2.65 | N9: 4.3 | O9: 6 | P9: 4.6 | Q9: 10.4 | S9: =SUM(M9:Q9) -> 27.95 | T9: =COUNTIFS($Y:$Y, Y9, $S:$S, ">"&S9) + 1 -> 9 | U9: =0.85*E9+T9*0.15 -> 9.85 | V9: =100.4-0.4*W9 -> 97.2 | W9: =COUNTIFS($Y:$Y, Y9, $U:$U, "<"&U9) + 1 -> 8 | X9: 64 | Y9: 能源与动力工程
A10: 235 | B10: 1120232359 | C10: 连奕晨 | D10: =VLOOKUP([1]成绩单!B10,[1]Sheet1!$A:$K,4,0) -> 精工2312 | E10: 9 | F10: 0.140625 | G10: 86.9586 | H10: 61 | I10: 139 | J10: 0 | K10: 0 | L10: 是 | M10: 2.2 | N10: 1 | O10: 2.35 | P10: 10.2 | Q10: 2.5 | S10: =SUM(M10:Q10) -> 18.25 | T10: =COUNTIFS($Y:$Y, Y10, $S:$S, ">"&S10) + 1 -> 16 | U10: =0.85*E10+T10*0.15 -> 10.05 | V10: =100.4-0.4*W10 -> 96.8 | W10: =COUNTIFS($Y:$Y, Y10, $U:$U, "<"&U10) + 1 -> 9 | X10: 64 | Y10: 能源与动力工程
A11: 236 | B11: 1120231776 | C11: 高居宸 | D11: =VLOOKUP([1]成绩单!B8,[1]Sheet1!$A:$K,4,0) -> 精工2313 | E11: 7 | F11: 0.109375 | G11: 87.117 | H11: 62 | I11: 141 | J11: 0 | K11: 0 | L11: 是 | M11: 1 | N11: 0 | O11: 1 | P11: 1.8 | Q11: 1 | S11: =SUM(M11:Q11) -> 4.8 | T11: =COUNTIFS($Y:$Y, Y11, $S:$S, ">"&S11) + 1 -> 38 | U11: =0.85*E11+T11*0.15 -> 11.65 | V11: =100.4-0.4*W11 -> 96.4 | W11: =COUNTIFS($Y:$Y, Y11, $U:$U, "<"&U11) + 1 -> 10 | X11: 64 | Y11: 能源与动力工程
A12: 237 | B12: 1120231028 | C12: 叶佳玮 | D12: =VLOOKUP([1]成绩单!B13,[1]Sheet1!$A:$K,4,0) -> 精工2313 | E12: 12 | F12: 0.1875 | G12: 83.964 | H12: 61 | I12: 139 | J12: 0 | K12: 0 | L12: 是 | M12: 2.3 | N12: 3.5 | O12: 4.3 | P12: 4.8 | Q12: 9.7 | S12: =SUM(M12:Q12) -> 24.6 | T12: =COUNTIFS($Y:$Y, Y12, $S:$S, ">"&S12) + 1 -> 12 | U12: =0.85*E12+T12*0.15 -> 12 | V12: =100.4-0.4*W12 -> 96 | W12: =COUNTIFS($Y:$Y, Y12, $U:$U, "<"&U12) + 1 -> 11 | X12: 64 | Y12: 能源与动力工程
A13: 238 | B13: 1120230999 | C13: 杨宁 | D13: =VLOOKUP([1]成绩单!B12,[1]Sheet1!$A:$K,4,0) -> 精工2312 | E13: 11 | F13: 0.171875 | G13: 84.6303 | H13: 63 | I13: 142 | J13: 0 | K13: 0 | L13: 是 | M13: 0.15 | N13: 4 | O13: 1.8 | P13: 2.2 | Q13: 2 | S13: =SUM(M13:Q13) -> 10.15 | T13: =COUNTIFS($Y:$Y, Y13, $S:$S, ">"&S13) + 1 -> 26 | U13: =0.85*E13+T13*0.15 -> 13.25 | V13: =100.4-0.4*W13 -> 95.6 | W13: =COUNTIFS($Y:$Y, Y13, $U:$U, "<"&U13) + 1 -> 12 | X13: 64 | Y13: 能源与动力工程
A14: 239 | B14: 1120231760 | C14: 刘谕林 | D14: =VLOOKUP([1]成绩单!B14,[1]Sheet1!$A:$K,4,0) -> 精工2313 | E14: 13 | F14: 0.203125 | G14: 83.8549 | H14: 63 | I14: 143 | J14: 0 | K14: 0 | L14: 是 | M14: 2.4 | N14: 2.7 | O14: 4.8 | P14: 4.3 | Q14: 6.2 | S14: =SUM(M14:Q14) -> 20.4 | T14: =COUNTIFS($Y:$Y, Y14, $S:$S, ">"&S14) + 1 -> 15 | U14: =0.85*E14+T14*0.15 -> 13.3 | V14: =100.4-0.4*W14 -> 95.2 | W14: =COUNTIFS($Y:$Y, Y14, $U:$U, "<"&U14) + 1 -> 13 | X14: 64 | Y14: 能源与动力工程
A15: 240 | B15: 1120232044 | C15: 谭凯阳 | D15: =VLOOKUP([1]成绩单!B17,[1]Sheet1!$A:$K,4,0) -> 精工2313 | E15: 16 | F15: 0.25 | G15: 83.3129 | H15: 61 | I15: 139 | J15: 0 | K15: 0 | L15: 是 | M15: 4.5 | N15: 2 | O15: 7.1 | P15: 15.8 | Q15: 8.7 | S15: =SUM(M15:Q15) -> 38.1 | T15: =COUNTIFS($Y:$Y, Y15, $S:$S, ">"&S15) + 1 -> 1 | U15: =0.85*E15+T15*0.15 -> 13.75 | V15: =100.4-0.4*W15 -> 94.8 | W15: =COUNTIFS($Y:$Y, Y15, $U:$U, "<"&U15) + 1 -> 14 | X15: 64 | Y15: 能源与动力工程
A16: 241 | B16: 1120232500 | C16: 何思明 | D16: =VLOOKUP([1]成绩单!B15,[1]Sheet1!$A:$K,4,0) -> 精工2311 | E16: 14 | F16: 0.21875 | G16: 83.5556 | H16: 62 | I16: 139.5 | J16: 0 | K16: 0 | L16: 是 | M16: 1.6 | N16: 2.2 | O16: 0.7 | P16: 5.9 | Q16: 2.7 | S16: =SUM(M16:Q16) -> 13.1 | T16: =COUNTIFS($Y:$Y, Y16, $S:$S, ">"&S16) + 1 -> 20 | U16: =0.85*E16+T16*0.15 -> 14.9 | V16: =100.4-0.4*W16 -> 94.4 | W16: =COUNTIFS($Y:$Y, Y16, $U:$U, "<"&U16) + 1 -> 15 | X16: 64 | Y16: 能源与动力工程
A17: 242 | B17: 1120231264 | C17: 俸杨珂 | D17: =VLOOKUP([1]成绩单!B16,[1]Sheet1!$A:$K,4,0) -> 精工2310 | E17: 15 | F17: 0.234375 | G17: 83.3794 | H17: 62 | I17: 141 | J17: 0 | K17: 0 | L17: 是 | M17: 1.3 | N17: 1 | O17: 2.55 | P17: 3.5 | Q17: 6 | S17: =SUM(M17:Q17) -> 14.35 | T17: =COUNTIFS($Y:$Y, Y17, $S:$S, ">"&S17) + 1 -> 19 | U17: =0.85*E17+T17*0.15 -> 15.6 | V17: =100.4-0.4*W17 -> 94 | W17: =COUNTIFS($Y:$Y, Y17, $U:$U, "<"&U17) + 1 -> 16 | X17: 64 | Y17: 能源与动力工程
A18: 243 | B18: 1120232313 | C18: 王骏玮 | D18: =VLOOKUP([1]成绩单!B20,[1]Sheet1!$A:$K,4,0) -> 精工2312 | E18: 19 | F18: 0.296875 | G18: 82.4677 | H18: 66 | I18: 147 | J18: 0 | K18: 0 | L18: 是 | M18: 3.2 | N18: 2 | O18: 5 | P18: 16.9 | Q18: 6.3 | S18: =SUM(M18:Q18) -> 33.4 | T18: =COUNTIFS($Y:$Y, Y18, $S:$S, ">"&S18) + 1 -> 4 | U18: =0.85*E18+T18*0.15 -> 16.75 | V18: =100.4-0.4*W18 -> 93.6 | W18: =COUNTIFS($Y:$Y, Y18, $U:$U, "<"&U18) + 1 -> 17 | X18: 64 | Y18: 能源与动力工程
A19: 244 | B19: 1120231749 | C19: 王子木 | D19: =VLOOKUP([1]成绩单!B18,[1]Sheet1!$A:$K,4,0) -> 精工2311 | E19: 17 | F19: 0.265625 | G19: 83.088 | H19: 63 | I19: 142 | J19: 0 | K19: 0 | L19: 是 | M19: 0.35 | N19: 0.4 | O19: 1.5 | P19: 2.7 | Q19: 1.2 | S19: =SUM(M19:Q19) -> 6.15 | T19: =COUNTIFS($Y:$Y, Y19, $S:$S, ">"&S19) + 1 -> 35 | U19: =0.85*E19+T19*0.15 -> 19.7 | V19: =100.4-0.4*W19 -> 93.2 | W19: =COUNTIFS($Y:$Y, Y19, $U:$U, "<"&U19) + 1 -> 18 | X19: 64 | Y19: 能源与动力工程
A20: 245 | B20: 1120231276 | C20: 陈玺 | D20: =VLOOKUP([1]成绩单!B22,[1]Sheet1!$A:$K,4,0) -> 精工2310 | E20: 21 | F20: 0.328125 | G20: 81.2464 | H20: 62 | I20: 139 | J20: 0 | K20: 0 | L20: 否 | M20: 2.5 | N20: 1 | O20: 4 | P20: 2 | Q20: 6.2 | S20: =SUM(M20:Q20) -> 15.7 | T20: =COUNTIFS($Y:$Y, Y20, $S:$S, ">"&S20) + 1 -> 17 | U20: =0.85*E20+T20*0.15 -> 20.4 | V20: =100.4-0.4*W20 -> 92.8 | W20: =COUNTIFS($Y:$Y, Y20, $U:$U, "<"&U20) + 1 -> 19 | X20: 64 | Y20: 能源与动力工程
A21: 246 | B21: 1120231759 | C21: 王天宋 | D21: =VLOOKUP([1]成绩单!B21,[1]Sheet1!$A:$K,4,0) -> 精工2313 | E21: 20 | F21: 0.3125 | G21: 81.9137 | H21: 61 | I21: 139 | J21: 1 | K21: 1 | L21: 是 | M21: 1.5 | N21: 1.615 | O21: 2 | P21: 1 | Q21: 4.5 | S21: =SUM(M21:Q21) -> 10.615 | T21: =COUNTIFS($Y:$Y, Y21, $S:$S, ">"&S21) + 1 -> 24 | U21: =0.85*E21+T21*0.15 -> 20.6 | V21: =100.4-0.4*W21 -> 92.4 | W21: =COUNTIFS($Y:$Y, Y21, $U:$U, "<"&U21) + 1 -> 20 | X21: 64 | Y21: 能源与动力工程
A22: 247 | B22: 1120230827 | C22: 李泉霖 | D22: =VLOOKUP([1]成绩单!B19,[1]Sheet1!$A:$K,4,0) -> 精工2311 | E22: 18 | F22: 0.28125 | G22: 82.9307 | H22: 60 | I22: 137 | J22: 0 | K22: 0 | L22: 是 | M22: 0.7 | N22: 0.8 | O22: 0 | P22: 0.85 | Q22: 1 | S22: =SUM(M22:Q22) -> 3.35 | T22: =COUNTIFS($Y:$Y, Y22, $S:$S, ">"&S22) + 1 -> 42 | U22: =0.85*E22+T22*0.15 -> 21.6 | V22: =100.4-0.4*W22 -> 92 | W22: =COUNTIFS($Y:$Y, Y22, $U:$U, "<"&U22) + 1 -> 21 | X22: 64 | Y22: 能源与动力工程
